Workbook

Sheet physics_results
A1: datetime | B1: ai_model | C1: statement_row_id | D1: statement | E1: ok | F1: final_numeric | G1: final_formula | H1: final_units | I1: error | J1: raw_response_text | K1: full_api_response | L1: prompt_tokens | M1: completion_tokens | N1: total_tokens | O1: prompt_version | P1: topic | Q1: cost | R1: is_correct_number | S1: is_correct_formula | T1: is_correct_units
A2: 2026-06-03-13-14-20 | B2: anthropic/claude-opus-4.7 | C2: 1 | D2: Частица пролетает расстояние l = 2 м равномерно, а затем тормозит с ускорением а = 5*10^5 м/с^2. При какой скорости частицы время движения ее от вылета до остановки будет наименьшим? Examples: Example 1: Calculate the height of a cliff if it takes 2.35 s for a rock to hit the ground when it is thrown straight up from the cliff with an initial velocity of 8.00 m/s. (b) How long would it take to reach the ground if it is thrown straight down with the same speed?* Solution s ↑ y₀ = ? ////| /\ | / \ | / \ | / ↓ | / | |______/________|____ y = 0 m (a) Knowns: \(t = 2.35\ \text{s}; y = 0\ \text{m}; v_0 = +8.00\ \text{m/s}; a = -9.8\ \text{m/s}^2\) Since we know \(t\), \(y\), \(v_0\), and \(a\) and want to find \(y_0\), we can use the equation \[ y = y_0 + v_0t + \frac{1}{2}at^2. \] \[ y = (0\ \text{m}) + (+8.00\ \text{m/s})(2.35\ \text{s}) + \frac{1}{2}(-9.80\ \text{m/s}^2)(2.35\ \text{s})^2 = -8.26\ \text{m}, \text{ so the cliff is} \] <u>8.26 m</u> high. (b) Knowns: \(y = 0\ \text{m}; y_0 = 8.26\ \text{m}; v_0 = -8.00\ \text{m/s}; a = -9.80\ \text{m/s}^2\) Now we know \(y\), \(y_0\), \(v_0\), and \(a\) and want to find \(t\), so we use the equation \[ y = y_0 + v_0t + \frac{1}{2}at^2 \] again. Rearranging, \[ t = \frac{-v_0 \pm \sqrt{v_0^2 - 4(0.5a)(y_0 - y)}}{2(0.5a)} \] \[ t = \frac{-(-8.00\ \text{m/s}) \pm \sqrt{(-8.00\ \text{m/s})^2 + 2(9.80\ \text{m/s}^2)(8.26\ \text{m} - 0\ \text{m})}}{(-9.80\ \text{m/s}^2)} \] \[ = \frac{8.00\ \text{m/s} \pm 15.03\ \text{m/s}}{-9.80\ \text{m/s}^2} \] \[ t = 0.717\ \text{s} \text{ or } -2.35\ \text{s} \Rightarrow t = \underline{0.717\ \text{s}} \] Example 2: *Calculate the force a 70.0-kg high jumper must exert on the ground to produce an upward acceleration 4.00 times the acceleration due to gravity. Explicitly show how you follow the steps in the Problem-Solving Strategy for Newton’s laws of motion.* Solution Step 1. Use Newton’s Laws of Motion. ↑ F | | (m) ↑ a | ↓ w Force acting on the high jumper. Step 2. Given: \(a = 4.00\ g = (4.00)(9.80\ \text{m/s}^2) = 39.2\ \text{m/s}^2;\ m = 70.0\ \text{kg}\) Find \(F\). Step 3. \(\sum F = +F - w = ma,\) so that \(F = ma + w = ma + mg = m(a + g)\) \[ F = (70.0\ \text{kg})[(39.2\ \text{m/s}^2) + (9.80\ \text{m/s}^2)] = \underline{3.43 \times 10^3\ \text{N}} \] The force exerted by the high-jumper is actually down on the ground, but F is up from the ground to help him jump. Step 4. This result is reasonable, since it is quite possible for a person to exert a force of the magnitude of \(10^3\ \text{N}\). Example 3: *A shopper pushes a grocery cart 20.0 m at constant speed on level ground, against a 35.0 N frictional force. He pushes in a direction 25.0° below the horizontal. (a) What is the work done on the cart by friction? (b) What is the work done on the cart by the gravitational force? (c) What is the work done on the cart by the shopper? (d) Find the force the shopper exerts, using energy considerations. (e) What is the total work done on the cart?* Solution (a) The work done by friction is in the opposite direction of the motion, so \(\theta = 180^\circ\), and therefore \(W_f = Fd \cos\theta = 35.0\ \text{N} \times 20.0\ \text{m} \times \cos 180^\circ = \underline{-700\ \text{J}}\) (b) The work done by gravity is perpendicular to the direction of motion, so \(\theta = 90^\circ\), and \(W_g = Fd \cos\theta = 35.0\ \text{N} \times 20.0\ \text{m} \times \cos 90^\circ = \underline{0\ \text{J}}\) (c) If the cart moves at a constant speed, no energy is transferred to it, from the work-energy theorem: \(\text{net } W = W_s + W_f = 0,\) or \(W_s = \underline{700\ \text{J}}\) (d) Use the equation \(W_s = Fd \cos\theta\), where \(\theta = 25^\circ\), and solve for the force: \[ F = \frac{W_s}{d \cos\theta} = \frac{700\ \text{J}}{20.0\ \text{m} \times \cos 25^\circ} = 38.62\ \text{N} = \underline{38.6\ \text{N}} \] (e) Since there is no change in speed, the work energy theorem says that there is no net work done on the cart: \(\text{net } W = W_f + W_s = -700\ \text{J} + 700\ \text{J} = \underline{0\ \text{J}}\) | E2: TRUE | F2: 1414.21 | G2: v=\sqrt{2al} | H2: m/s | J2: {"final_numeric":1414.21,"final_formula":"v=\\sqrt{2al}","final_units":"m/s"} | K2: {'id': 'gen-1780478058-z0ViJnvuAXLmt9Hs99ZQ', 'object': 'chat.completion', 'created': 1780478058, 'model': 'anthropic/claude-4.7-opus-20260416', 'provider': 'Anthropic', 'system_fingerprint': None, 'service_tier': 'default', 'choices': [{'index': 0, 'logprobs': None, 'finish_reason': 'stop', 'native_finish_reason': 'end_turn', 'message': {'role': 'assistant', 'content': '{"final_numeric":1414.21,"final_formula":"v=\\\\sqrt{2al}","final_units":"m/s"}', 'refusal': None, 'reasoning': None}}], 'usage': {'prompt_tokens': 2910, 'completion_tokens': 47, 'total_tokens': 2957, 'cost': 0.015725, 'is_byok': False, 'prompt_tokens_details': {'cached_tokens': 0, 'cache_write_tokens': 0, 'audio_tokens': 0, 'video_tokens': 0}, 'cost_details': {'upstream_inference_cost': 0.015725, 'upstream_inference_prompt_cost': 0.01455, 'upstream_inference_completions_cost': 0.001175}, 'completion_tokens_details': {'reasoning_tokens': 0, 'image_tokens': 0, 'audio_tokens': 0}}} | L2: 2910 | M2: 47 | N2: 2957 | O2: 0 | P2: =VLOOKUP(C2,problems!$A$2:$B$26,2) -> mechanics | Q2: =IFERROR(__xludf.DUMMYFUNCTION("INDEX(FILTER('stats2-openrouter_activity_2026'!C:C,L2='stats2-openrouter_activity_2026'!H:H,M2='stats2-openrouter_activity_2026'!I:I, B2='stats2-openrouter_activity_2026'!M:M),1)"),0.015725) -> 0.015725 | R2: =IFS( F2=VLOOKUP($C2,problems!$A$2:$G$26,6),1, True,0 ) -> 0 | S2: =IFS( G2=VLOOKUP($C2,problems!$A$2:$G$26,4),1, G2=VLOOKUP($C2,problems!$A$2:$G$26,5),1, True,0 ) -> 0 | T2: =IFS( H2=VLOOKUP($C2,problems!$A$2:$G$26,7),1, True,0 ) -> 1
A3: 2026-06-03-13-17-15 | B3: anthropic/claude-opus-4.7 | C3: 2 | D3: Точка движется по прямой согласно закону х = At + Bt^3, где А = 6 м/с; В = -0,125 м/с^3. Определить: среднюю скорость точки в интервале времени от t_{1} = 2 с до t_{2} = 6 с; Examples: Example 1: Calculate the height of a cliff if it takes 2.35 s for a rock to hit the ground when it is thrown straight up from the cliff with an initial velocity of 8.00 m/s. (b) How long would it take to reach the ground if it is thrown straight down with the same speed?* Solution s ↑ y₀ = ? ////| /\ | / \ | / \ | / ↓ | / | |______/________|____ y = 0 m (a) Knowns: \(t = 2.35\ \text{s}; y = 0\ \text{m}; v_0 = +8.00\ \text{m/s}; a = -9.8\ \text{m/s}^2\) Since we know \(t\), \(y\), \(v_0\), and \(a\) and want to find \(y_0\), we can use the equation \[ y = y_0 + v_0t + \frac{1}{2}at^2. \] \[ y = (0\ \text{m}) + (+8.00\ \text{m/s})(2.35\ \text{s}) + \frac{1}{2}(-9.80\ \text{m/s}^2)(2.35\ \text{s})^2 = -8.26\ \text{m}, \text{ so the cliff is} \] <u>8.26 m</u> high. (b) Knowns: \(y = 0\ \text{m}; y_0 = 8.26\ \text{m}; v_0 = -8.00\ \text{m/s}; a = -9.80\ \text{m/s}^2\) Now we know \(y\), \(y_0\), \(v_0\), and \(a\) and want to find \(t\), so we use the equation \[ y = y_0 + v_0t + \frac{1}{2}at^2 \] again. Rearranging, \[ t = \frac{-v_0 \pm \sqrt{v_0^2 - 4(0.5a)(y_0 - y)}}{2(0.5a)} \] \[ t = \frac{-(-8.00\ \text{m/s}) \pm \sqrt{(-8.00\ \text{m/s})^2 + 2(9.80\ \text{m/s}^2)(8.26\ \text{m} - 0\ \text{m})}}{(-9.80\ \text{m/s}^2)} \] \[ = \frac{8.00\ \text{m/s} \pm 15.03\ \text{m/s}}{-9.80\ \text{m/s}^2} \] \[ t = 0.717\ \text{s} \text{ or } -2.35\ \text{s} \Rightarrow t = \underline{0.717\ \text{s}} \] Example 2: *Calculate the force a 70.0-kg high jumper must exert on the ground to produce an upward acceleration 4.00 times the acceleration due to gravity. Explicitly show how you follow the steps in the Problem-Solving Strategy for Newton’s laws of motion.* Solution Step 1. Use Newton’s Laws of Motion. ↑ F | | (m) ↑ a | ↓ w Force acting on the high jumper. Step 2. Given: \(a = 4.00\ g = (4.00)(9.80\ \text{m/s}^2) = 39.2\ \text{m/s}^2;\ m = 70.0\ \text{kg}\) Find \(F\). Step 3. \(\sum F = +F - w = ma,\) so that \(F = ma + w = ma + mg = m(a + g)\) \[ F = (70.0\ \text{kg})[(39.2\ \text{m/s}^2) + (9.80\ \text{m/s}^2)] = \underline{3.43 \times 10^3\ \text{N}} \] The force exerted by the high-jumper is actually down on the ground, but F is up from the ground to help him jump. Step 4. This result is reasonable, since it is quite possible for a person to exert a force of the magnitude of \(10^3\ \text{N}\). Example 3: *A shopper pushes a grocery cart 20.0 m at constant speed on level ground, against a 35.0 N frictional force. He pushes in a direction 25.0° below the horizontal. (a) What is the work done on the cart by friction? (b) What is the work done on the cart by the gravitational force? (c) What is the work done on the cart by the shopper? (d) Find the force the shopper exerts, using energy considerations. (e) What is the total work done on the cart?* Solution (a) The work done by friction is in the opposite direction of the motion, so \(\theta = 180^\circ\), and therefore \(W_f = Fd \cos\theta = 35.0\ \text{N} \times 20.0\ \text{m} \times \cos 180^\circ = \underline{-700\ \text{J}}\) (b) The work done by gravity is perpendicular to the direction of motion, so \(\theta = 90^\circ\), and \(W_g = Fd \cos\theta = 35.0\ \text{N} \times 20.0\ \text{m} \times \cos 90^\circ = \underline{0\ \text{J}}\) (c) If the cart moves at a constant speed, no energy is transferred to it, from the work-energy theorem: \(\text{net } W = W_s + W_f = 0,\) or \(W_s = \underline{700\ \text{J}}\) (d) Use the equation \(W_s = Fd \cos\theta\), where \(\theta = 25^\circ\), and solve for the force: \[ F = \frac{W_s}{d \cos\theta} = \frac{700\ \text{J}}{20.0\ \text{m} \times \cos 25^\circ} = 38.62\ \text{N} = \underline{38.6\ \text{N}} \] (e) Since there is no change in speed, the work energy theorem says that there is no net work done on the cart: \(\text{net } W = W_f + W_s = -700\ \text{J} + 700\ \text{J} = \underline{0\ \text{J}}\) | E3: TRUE | F3: -0.5 | G3: \bar{v}=\frac{x(t_2)-x(t_1)}{t_2-t_1}=\frac{(At_2+Bt_2^3)-(At_1+Bt_1^3)}{t_2-t_1} | H3: m/s | J3: x(2)=12-0.125·8=11; x(6)=36-0.125·216=36-27=9; Δx=-2; Δt=4; v=-0.5 {"final_numeric":-0.5,"final_formula":"\\bar{v}=\\frac{x(t_2)-x(t_1)}{t_2-t_1}=\\frac{(At_2+Bt_2^3)-(At_1+Bt_1^3)}{t_2-t_1}","final_units":"m/s"} | K3: {'id': 'gen-1780478232-aOq3P3i0HH77RRU1BumA', 'object': 'chat.completion', 'created': 1780478232, 'model': 'anthropic/claude-4.7-opus-20260416', 'provider': 'Anthropic', 'system_fingerprint': None, 'service_tier': 'default', 'choices': [{'index': 0, 'logprobs': None, 'finish_reason': 'stop', 'native_finish_reason': 'end_turn', 'message': {'role': 'assistant', 'content': 'x(2)=12-0.125·8=11; x(6)=36-0.125·216=36-27=9; Δx=-2; Δt=4; v=-0.5\n\n{"final_numeric":-0.5,"final_formula":"\\\\bar{v}=\\\\frac{x(t_2)-x(t_1)}{t_2-t_1}=\\\\frac{(At_2+Bt_2^3)-(At_1+Bt_1^3)}{t_2-t_1}","final_units":"m/s"}', 'refusal': None, 'reasoning': None}}], 'usage': {'prompt_tokens': 2920, 'completion_tokens': 168, 'total_tokens': 3088, 'cost': 0.0188, 'is_byok': False, 'prompt_tokens_details': {'cached_tokens': 0, 'cache_write_tokens': 0, 'audio_tokens': 0, 'video_tokens': 0}, 'cost_details': {'upstream_inference_cost': 0.0188, 'upstream_inference_prompt_cost': 0.0146, 'upstream_inference_completions_cost': 0.0042}, 'completion_tokens_details': {'reasoning_tokens': 0, 'image_tokens': 0, 'audio_tokens': 0}}} | L3: 2920 | M3: 168 | N3: 3088 | O3: 0 | P3: =VLOOKUP(C3,problems!$A$2:$B$26,2) -> mechanics | Q3: =IFERROR(__xludf.DUMMYFUNCTION("INDEX(FILTER('stats2-openrouter_activity_2026'!C:C,L3='stats2-openrouter_activity_2026'!H:H,M3='stats2-openrouter_activity_2026'!I:I, B3='stats2-openrouter_activity_2026'!M:M),1)"),0.0188) -> 0.0188 | R3: =IFS( F3=VLOOKUP($C3,problems!$A$2:$G$26,6),1, True,0 ) -> 1 | S3: =IFS( G3=VLOOKUP($C3,problems!$A$2:$G$26,4),1, G3=VLOOKUP($C3,problems!$A$2:$G$26,5),1, True,0 ) -> 0 | T3: =IFS( H3=VLOOKUP($C3,problems!$A$2:$G$26,7),1, True,0 ) -> 1
A4: 2026-06-03-13-20-51 | B4: anthropic/claude-opus-4.7 | C4: 3 | D4: A truck is traveling east at 80 km/h. At an intersection 32 km ahead, a car is traveling north at 50 km/h. How long in hours after this moment will the vehicles be closest to each other? Examples: Example 1: Calculate the height of a cliff if it takes 2.35 s for a rock to hit the ground when it is thrown straight up from the cliff with an initial velocity of 8.00 m/s. (b) How long would it take to reach the ground if it is thrown straight down with the same speed?* Solution s ↑ y₀ = ? ////| /\ | / \ | / \ | / ↓ | / | |______/________|____ y = 0 m (a) Knowns: \(t = 2.35\ \text{s}; y = 0\ \text{m}; v_0 = +8.00\ \text{m/s}; a = -9.8\ \text{m/s}^2\) Since we know \(t\), \(y\), \(v_0\), and \(a\) and want to find \(y_0\), we can use the equation \[ y = y_0 + v_0t + \frac{1}{2}at^2. \] \[ y = (0\ \text{m}) + (+8.00\ \text{m/s})(2.35\ \text{s}) + \frac{1}{2}(-9.80\ \text{m/s}^2)(2.35\ \text{s})^2 = -8.26\ \text{m}, \text{ so the cliff is} \] <u>8.26 m</u> high. (b) Knowns: \(y = 0\ \text{m}; y_0 = 8.26\ \text{m}; v_0 = -8.00\ \text{m/s}; a = -9.80\ \text{m/s}^2\) Now we know \(y\), \(y_0\), \(v_0\), and \(a\) and want to find \(t\), so we use the equation \[ y = y_0 + v_0t + \frac{1}{2}at^2 \] again. Rearranging, \[ t = \frac{-v_0 \pm \sqrt{v_0^2 - 4(0.5a)(y_0 - y)}}{2(0.5a)} \] \[ t = \frac{-(-8.00\ \text{m/s}) \pm \sqrt{(-8.00\ \text{m/s})^2 + 2(9.80\ \text{m/s}^2)(8.26\ \text{m} - 0\ \text{m})}}{(-9.80\ \text{m/s}^2)} \] \[ = \frac{8.00\ \text{m/s} \pm 15.03\ \text{m/s}}{-9.80\ \text{m/s}^2} \] \[ t = 0.717\ \text{s} \text{ or } -2.35\ \text{s} \Rightarrow t = \underline{0.717\ \text{s}} \] Example 2: *Calculate the force a 70.0-kg high jumper must exert on the ground to produce an upward acceleration 4.00 times the acceleration due to gravity. Explicitly show how you follow the steps in the Problem-Solving Strategy for Newton’s laws of motion.* Solution Step 1. Use Newton’s Laws of Motion. ↑ F | | (m) ↑ a | ↓ w Force acting on the high jumper. Step 2. Given: \(a = 4.00\ g = (4.00)(9.80\ \text{m/s}^2) = 39.2\ \text{m/s}^2;\ m = 70.0\ \text{kg}\) Find \(F\). Step 3. \(\sum F = +F - w = ma,\) so that \(F = ma + w = ma + mg = m(a + g)\) \[ F = (70.0\ \text{kg})[(39.2\ \text{m/s}^2) + (9.80\ \text{m/s}^2)] = \underline{3.43 \times 10^3\ \text{N}} \] The force exerted by the high-jumper is actually down on the ground, but F is up from the ground to help him jump. Step 4. This result is reasonable, since it is quite possible for a person to exert a force of the magnitude of \(10^3\ \text{N}\). Example 3: *A shopper pushes a grocery cart 20.0 m at constant speed on level ground, against a 35.0 N frictional force. He pushes in a direction 25.0° below the horizontal. (a) What is the work done on the cart by friction? (b) What is the work done on the cart by the gravitational force? (c) What is the work done on the cart by the shopper? (d) Find the force the shopper exerts, using energy considerations. (e) What is the total work done on the cart?* Solution (a) The work done by friction is in the opposite direction of the motion, so \(\theta = 180^\circ\), and therefore \(W_f = Fd \cos\theta = 35.0\ \text{N} \times 20.0\ \text{m} \times \cos 180^\circ = \underline{-700\ \text{J}}\) (b) The work done by gravity is perpendicular to the direction of motion, so \(\theta = 90^\circ\), and \(W_g = Fd \cos\theta = 35.0\ \text{N} \times 20.0\ \text{m} \times \cos 90^\circ = \underline{0\ \text{J}}\) (c) If the cart moves at a constant speed, no energy is transferred to it, from the work-energy theorem: \(\text{net } W = W_s + W_f = 0,\) or \(W_s = \underline{700\ \text{J}}\) (d) Use the equation \(W_s = Fd \cos\theta\), where \(\theta = 25^\circ\), and solve for the force: \[ F = \frac{W_s}{d \cos\theta} = \frac{700\ \text{J}}{20.0\ \text{m} \times \cos 25^\circ} = 38.62\ \text{N} = \underline{38.6\ \text{N}} \] (e) Since there is no change in speed, the work energy theorem says that there is no net work done on the cart: \(\text{net } W = W_f + W_s = -700\ \text{J} + 700\ \text{J} = \underline{0\ \text{J}}\) | E4: TRUE | F4: 0.2872 | G4: t=\frac{80\cdot32}{80^2+50^2} | H4: h | J4: {"final_numeric":0.2872,"final_formula":"t=\\frac{80\\cdot32}{80^2+50^2}","final_units":"h"} | K4: {'id': 'gen-1780478450-e4ln6HTIHSLBWHnapZro', 'object': 'chat.completion', 'created': 1780478450, 'model': 'anthropic/claude-4.7-opus-20260416', 'provider': 'Anthropic', 'system_fingerprint': None, 'service_tier': 'default', 'choices': [{'index': 0, 'logprobs': None, 'finish_reason': 'stop', 'native_finish_reason': 'end_turn', 'message': {'role': 'assistant', 'content': '{"final_numeric":0.2872,"final_formula":"t=\\\\frac{80\\\\cdot32}{80^2+50^2}","final_units":"h"}', 'refusal': None, 'reasoning': None}}], 'usage': {'prompt_tokens': 2897, 'completion_tokens': 57, 'total_tokens': 2954, 'cost': 0.01591, 'is_byok': False, 'prompt_tokens_details': {'cached_tokens': 0, 'cache_write_tokens': 0, 'audio_tokens': 0, 'video_tokens': 0}, 'cost_details': {'upstream_inference_cost': 0.01591, 'upstream_inference_prompt_cost': 0.014485, 'upstream_inference_completions_cost': 0.001425}, 'completion_tokens_details': {'reasoning_tokens': 0, 'image_tokens': 0, 'audio_tokens': 0}}} | L4: 2897 | M4: 57 | N4: 2954 | O4: 0 | P4: =VLOOKUP(C4,problems!$A$2:$B$26,2) -> mechanics | Q4: =IFERROR(__xludf.DUMMYFUNCTION("INDEX(FILTER('stats2-openrouter_activity_2026'!C:C,L4='stats2-openrouter_activity_2026'!H:H,M4='stats2-openrouter_activity_2026'!I:I, B4='stats2-openrouter_activity_2026'!M:M),1)"),0.01591) -> 0.01591 | R4: =IFS( F4=VLOOKUP($C4,problems!$A$2:$G$26,6),1, True,0 ) -> 0 | S4: =IFS( G4=VLOOKUP($C4,problems!$A$2:$G$26,4),1, G4=VLOOKUP($C4,problems!$A$2:$G$26,5),1, True,0 ) -> 0 | T4: =IFS( H4=VLOOKUP($C4,problems!$A$2:$G$26,7),1, True,0 ) -> 1
A5: 2026-06-03-13-26-47 | B5: anthropic/claude-opus-4.7 | C5: 4 | D5: Закон движения материальной точки имеет вид: х = а_{1} + b_{1}*t + y_{1}*t^2; y = α_{2} + b_{2}*t + y_{2}*t^2, где b_{1} = b_{2} = 1 м/с, y_{1}= -1 м/с^2, y_{2} = 2 м/с^2. Каково ее ускорение? Определить угол между скоростью и ускорением в момент времени t = 1 с. Examples: Example 1: Calculate the height of a cliff if it takes 2.35 s for a rock to hit the ground when it is thrown straight up from the cliff with an initial velocity of 8.00 m/s. (b) How long would it take to reach the ground if it is thrown straight down with the same speed?* Solution s ↑ y₀ = ? ////| /\ | / \ | / \ | / ↓ | / | |______/________|____ y = 0 m (a) Knowns: \(t = 2.35\ \text{s}; y = 0\ \text{m}; v_0 = +8.00\ \text{m/s}; a = -9.8\ \text{m/s}^2\) Since we know \(t\), \(y\), \(v_0\), and \(a\) and want to find \(y_0\), we can use the equation \[ y = y_0 + v_0t + \frac{1}{2}at^2. \] \[ y = (0\ \text{m}) + (+8.00\ \text{m/s})(2.35\ \text{s}) + \frac{1}{2}(-9.80\ \text{m/s}^2)(2.35\ \text{s})^2 = -8.26\ \text{m}, \text{ so the cliff is} \] <u>8.26 m</u> high. (b) Knowns: \(y = 0\ \text{m}; y_0 = 8.26\ \text{m}; v_0 = -8.00\ \text{m/s}; a = -9.80\ \text{m/s}^2\) Now we know \(y\), \(y_0\), \(v_0\), and \(a\) and want to find \(t\), so we use the equation \[ y = y_0 + v_0t + \frac{1}{2}at^2 \] again. Rearranging, \[ t = \frac{-v_0 \pm \sqrt{v_0^2 - 4(0.5a)(y_0 - y)}}{2(0.5a)} \] \[ t = \frac{-(-8.00\ \text{m/s}) \pm \sqrt{(-8.00\ \text{m/s})^2 + 2(9.80\ \text{m/s}^2)(8.26\ \text{m} - 0\ \text{m})}}{(-9.80\ \text{m/s}^2)} \] \[ = \frac{8.00\ \text{m/s} \pm 15.03\ \text{m/s}}{-9.80\ \text{m/s}^2} \] \[ t = 0.717\ \text{s} \text{ or } -2.35\ \text{s} \Rightarrow t = \underline{0.717\ \text{s}} \] Example 2: *Calculate the force a 70.0-kg high jumper must exert on the ground to produce an upward acceleration 4.00 times the acceleration due to gravity. Explicitly show how you follow the steps in the Problem-Solving Strategy for Newton’s laws of motion.* Solution Step 1. Use Newton’s Laws of Motion. ↑ F | | (m) ↑ a | ↓ w Force acting on the high jumper. Step 2. Given: \(a = 4.00\ g = (4.00)(9.80\ \text{m/s}^2) = 39.2\ \text{m/s}^2;\ m = 70.0\ \text{kg}\) Find \(F\). Step 3. \(\sum F = +F - w = ma,\) so that \(F = ma + w = ma + mg = m(a + g)\) \[ F = (70.0\ \text{kg})[(39.2\ \text{m/s}^2) + (9.80\ \text{m/s}^2)] = \underline{3.43 \times 10^3\ \text{N}} \] The force exerted by the high-jumper is actually down on the ground, but F is up from the ground to help him jump. Step 4. This result is reasonable, since it is quite possible for a person to exert a force of the magnitude of \(10^3\ \text{N}\). Example 3: *A shopper pushes a grocery cart 20.0 m at constant speed on level ground, against a 35.0 N frictional force. He pushes in a direction 25.0° below the horizontal. (a) What is the work done on the cart by friction? (b) What is the work done on the cart by the gravitational force? (c) What is the work done on the cart by the shopper? (d) Find the force the shopper exerts, using energy considerations. (e) What is the total work done on the cart?* Solution (a) The work done by friction is in the opposite direction of the motion, so \(\theta = 180^\circ\), and therefore \(W_f = Fd \cos\theta = 35.0\ \text{N} \times 20.0\ \text{m} \times \cos 180^\circ = \underline{-700\ \text{J}}\) (b) The work done by gravity is perpendicular to the direction of motion, so \(\theta = 90^\circ\), and \(W_g = Fd \cos\theta = 35.0\ \text{N} \times 20.0\ \text{m} \times \cos 90^\circ = \underline{0\ \text{J}}\) (c) If the cart moves at a constant speed, no energy is transferred to it, from the work-energy theorem: \(\text{net } W = W_s + W_f = 0,\) or \(W_s = \underline{700\ \text{J}}\) (d) Use the equation \(W_s = Fd \cos\theta\), where \(\theta = 25^\circ\), and solve for the force: \[ F = \frac{W_s}{d \cos\theta} = \frac{700\ \text{J}}{20.0\ \text{m} \times \cos 25^\circ} = 38.62\ \text{N} = \underline{38.6\ \text{N}} \] (e) Since there is no change in speed, the work energy theorem says that there is no net work done on the cart: \(\text{net } W = W_f + W_s = -700\ \text{J} + 700\ \text{J} = \underline{0\ \text{J}}\) | E5: TRUE | F5: 119.74 | G5: \cos\theta = \frac{\vec{v}\cdot\vec{a}}{|\vec{v}||\vec{a}|} = \frac{(b_1+2\gamma_1 t)(2\gamma_1)+(b_2+2\gamma_2 t)(2\gamma_2)}{\sqrt{(b_1+2\gamma_1 t)^2+(b_2+2\gamma_2 t)^2}\cdot\sqrt{(2\gamma_1)^2+(2\gamma_2)^2}} | H5: degree | J5: {"final_numeric":119.74,"final_formula":"\\cos\\theta = \\frac{\\vec{v}\\cdot\\vec{a}}{|\\vec{v}||\\vec{a}|} = \\frac{(b_1+2\\gamma_1 t)(2\\gamma_1)+(b_2+2\\gamma_2 t)(2\\gamma_2)}{\\sqrt{(b_1+2\\gamma_1 t)^2+(b_2+2\\gamma_2 t)^2}\\cdot\\sqrt{(2\\gamma_1)^2+(2\\gamma_2)^2}}","final_units":"degree"} | K5: {'id': 'gen-1780478803-t0dGraWf6E2LcnSrIFfy', 'object': 'chat.completion', 'created': 1780478803, 'model': 'anthropic/claude-4.7-opus-20260416', 'provider': 'Anthropic', 'system_fingerprint': None, 'service_tier': 'default', 'choices': [{'index': 0, 'logprobs': None, 'finish_reason': 'stop', 'native_finish_reason': 'end_turn', 'message': {'role': 'assistant', 'content': '{"final_numeric":119.74,"final_formula":"\\\\cos\\\\theta = \\\\frac{\\\\vec{v}\\\\cdot\\\\vec{a}}{|\\\\vec{v}||\\\\vec{a}|} = \\\\frac{(b_1+2\\\\gamma_1 t)(2\\\\gamma_1)+(b_2+2\\\\gamma_2 t)(2\\\\gamma_2)}{\\\\sqrt{(b_1+2\\\\gamma_1 t)^2+(b_2+2\\\\gamma_2 t)^2}\\\\cdot\\\\sqrt{(2\\\\gamma_1)^2+(2\\\\gamma_2)^2}}","final_units":"degree"}', 'refusal': None, 'reasoning': None}}], 'usage': {'prompt_tokens': 2986, 'completion_tokens': 231, 'total_tokens': 3217, 'cost': 0.020705, 'is_byok': False, 'prompt_tokens_details': {'cached_tokens': 0, 'cache_write_tokens': 0, 'audio_tokens': 0, 'video_tokens': 0}, 'cost_details': {'upstream_inference_cost': 0.020705, 'upstream_inference_prompt_cost': 0.01493, 'upstream_inference_completions_cost': 0.005775}, 'completion_tokens_details': {'reasoning_tokens': 0, 'image_tokens': 0, 'audio_tokens': 0}}} | L5: 2986 | M5: 231 | N5: 3217 | O5: 0 | P5: =VLOOKUP(C5,problems!$A$2:$B$26,2) -> mechanics | Q5: =IFERROR(__xludf.DUMMYFUNCTION("INDEX(FILTER('stats2-openrouter_activity_2026'!C:C,L5='stats2-openrouter_activity_2026'!H:H,M5='stats2-openrouter_activity_2026'!I:I, B5='stats2-openrouter_activity_2026'!M:M),1)"),0.020705) -> 0.020705 | R5: =IFS( F5=VLOOKUP($C5,problems!$A$2:$G$26,6),1, True,0 ) -> 0 | S5: =IFS( G5=VLOOKUP($C5,problems!$A$2:$G$26,4),1, G5=VLOOKUP($C5,problems!$A$2:$G$26,5),1, True,0 ) -> 0 | T5: =IFS( H5=VLOOKUP($C5,problems!$A$2:$G$26,7),1, True,0 ) -> 0
A6: 2026-06-03-13-30-55 | B6: anthropic/claude-opus-4.7 | C6: 5 | D6: A crate is being pushed across a rough floor surface. If no force is applied on the crate, the crate will slow down and come to a stop. If the crate of mass 50 kg moving at speed 8 m/s comes to rest in 10 seconds, what is the rate at which the frictional force on the crate takes energy away from the crate? Examples: Example 1: Calculate the height of a cliff if it takes 2.35 s for a rock to hit the ground when it is thrown straight up from the cliff with an initial velocity of 8.00 m/s. (b) How long would it take to reach the ground if it is thrown straight down with the same speed?* Solution s ↑ y₀ = ? ////| /\ | / \ | / \ | / ↓ | / | |______/________|____ y = 0 m (a) Knowns: \(t = 2.35\ \text{s}; y = 0\ \text{m}; v_0 = +8.00\ \text{m/s}; a = -9.8\ \text{m/s}^2\) Since we know \(t\), \(y\), \(v_0\), and \(a\) and want to find \(y_0\), we can use the equation \[ y = y_0 + v_0t + \frac{1}{2}at^2. \] \[ y = (0\ \text{m}) + (+8.00\ \text{m/s})(2.35\ \text{s}) + \frac{1}{2}(-9.80\ \text{m/s}^2)(2.35\ \text{s})^2 = -8.26\ \text{m}, \text{ so the cliff is} \] <u>8.26 m</u> high. (b) Knowns: \(y = 0\ \text{m}; y_0 = 8.26\ \text{m}; v_0 = -8.00\ \text{m/s}; a = -9.80\ \text{m/s}^2\) Now we know \(y\), \(y_0\), \(v_0\), and \(a\) and want to find \(t\), so we use the equation \[ y = y_0 + v_0t + \frac{1}{2}at^2 \] again. Rearranging, \[ t = \frac{-v_0 \pm \sqrt{v_0^2 - 4(0.5a)(y_0 - y)}}{2(0.5a)} \] \[ t = \frac{-(-8.00\ \text{m/s}) \pm \sqrt{(-8.00\ \text{m/s})^2 + 2(9.80\ \text{m/s}^2)(8.26\ \text{m} - 0\ \text{m})}}{(-9.80\ \text{m/s}^2)} \] \[ = \frac{8.00\ \text{m/s} \pm 15.03\ \text{m/s}}{-9.80\ \text{m/s}^2} \] \[ t = 0.717\ \text{s} \text{ or } -2.35\ \text{s} \Rightarrow t = \underline{0.717\ \text{s}} \] Example 2: *Calculate the force a 70.0-kg high jumper must exert on the ground to produce an upward acceleration 4.00 times the acceleration due to gravity. Explicitly show how you follow the steps in the Problem-Solving Strategy for Newton’s laws of motion.* Solution Step 1. Use Newton’s Laws of Motion. ↑ F | | (m) ↑ a | ↓ w Force acting on the high jumper. Step 2. Given: \(a = 4.00\ g = (4.00)(9.80\ \text{m/s}^2) = 39.2\ \text{m/s}^2;\ m = 70.0\ \text{kg}\) Find \(F\). Step 3. \(\sum F = +F - w = ma,\) so that \(F = ma + w = ma + mg = m(a + g)\) \[ F = (70.0\ \text{kg})[(39.2\ \text{m/s}^2) + (9.80\ \text{m/s}^2)] = \underline{3.43 \times 10^3\ \text{N}} \] The force exerted by the high-jumper is actually down on the ground, but F is up from the ground to help him jump. Step 4. This result is reasonable, since it is quite possible for a person to exert a force of the magnitude of \(10^3\ \text{N}\). Example 3: *A shopper pushes a grocery cart 20.0 m at constant speed on level ground, against a 35.0 N frictional force. He pushes in a direction 25.0° below the horizontal. (a) What is the work done on the cart by friction? (b) What is the work done on the cart by the gravitational force? (c) What is the work done on the cart by the shopper? (d) Find the force the shopper exerts, using energy considerations. (e) What is the total work done on the cart?* Solution (a) The work done by friction is in the opposite direction of the motion, so \(\theta = 180^\circ\), and therefore \(W_f = Fd \cos\theta = 35.0\ \text{N} \times 20.0\ \text{m} \times \cos 180^\circ = \underline{-700\ \text{J}}\) (b) The work done by gravity is perpendicular to the direction of motion, so \(\theta = 90^\circ\), and \(W_g = Fd \cos\theta = 35.0\ \text{N} \times 20.0\ \text{m} \times \cos 90^\circ = \underline{0\ \text{J}}\) (c) If the cart moves at a constant speed, no energy is transferred to it, from the work-energy theorem: \(\text{net } W = W_s + W_f = 0,\) or \(W_s = \underline{700\ \text{J}}\) (d) Use the equation \(W_s = Fd \cos\theta\), where \(\theta = 25^\circ\), and solve for the force: \[ F = \frac{W_s}{d \cos\theta} = \frac{700\ \text{J}}{20.0\ \text{m} \times \cos 25^\circ} = 38.62\ \text{N} = \underline{38.6\ \text{N}} \] (e) Since there is no change in speed, the work energy theorem says that there is no net work done on the cart: \(\text{net } W = W_f + W_s = -700\ \text{J} + 700\ \text{J} = \underline{0\ \text{J}}\) | E6: TRUE | F6: 160 | G6: P = \frac{\frac{1}{2}mv^2}{t} = \frac{0.5 \times 50 \times 8^2}{10} | H6: W | J6: {"final_numeric":160,"final_formula":"P = \\frac{\\frac{1}{2}mv^2}{t} = \\frac{0.5 \\times 50 \\times 8^2}{10}","final_units":"W"} | K6: {'id': 'gen-1780479053-J2MI2nWPFY99tzEBuKrj', 'object': 'chat.completion', 'created': 1780479053, 'model': 'anthropic/claude-4.7-opus-20260416', 'provider': 'Anthropic', 'system_fingerprint': None, 'service_tier': 'default', 'choices': [{'index': 0, 'logprobs': None, 'finish_reason': 'stop', 'native_finish_reason': 'end_turn', 'message': {'role': 'assistant', 'content': '{"final_numeric":160,"final_formula":"P = \\\\frac{\\\\frac{1}{2}mv^2}{t} = \\\\frac{0.5 \\\\times 50 \\\\times 8^2}{10}","final_units":"W"}', 'refusal': None, 'reasoning': None}}], 'usage': {'prompt_tokens': 2935, 'completion_tokens': 82, 'total_tokens': 3017, 'cost': 0.016725, 'is_byok': False, 'prompt_tokens_details': {'cached_tokens': 0, 'cache_write_tokens': 0, 'audio_tokens': 0, 'video_tokens': 0}, 'cost_details': {'upstream_inference_cost': 0.016725, 'upstream_inference_prompt_cost': 0.014675, 'upstream_inference_completions_cost': 0.00205}, 'completion_tokens_details': {'reasoning_tokens': 0, 'image_tokens': 0, 'audio_tokens': 0}}} | L6: 2935 | M6: 82 | N6: 3017 | O6: 0 | P6: =VLOOKUP(C6,problems!$A$2:$B$26,2) -> mechanics | Q6: =IFERROR(__xludf.DUMMYFUNCTION("INDEX(FILTER('stats2-openrouter_activity_2026'!C:C,L6='stats2-openrouter_activity_2026'!H:H,M6='stats2-openrouter_activity_2026'!I:I, B6='stats2-openrouter_activity_2026'!M:M),1)"),0.016725) -> 0.016725 | R6: =IFS( F6=VLOOKUP($C6,problems!$A$2:$G$26,6),1, True,0 ) -> 1 | S6: =IFS( G6=VLOOKUP($C6,problems!$A$2:$G$26,4),1, G6=VLOOKUP($C6,problems!$A$2:$G$26,5),1, True,0 ) -> 0 | T6: =IFS( H6=VLOOKUP($C6,problems!$A$2:$G$26,7),1, True,0 ) -> 0
A7: 2026-06-03-13-34-25 | B7: anthropic/claude-opus-4.7 | C7: 6 | D7: Eight bumper cars, each with a mass of 322 kg, are running in a room 21.0 m long and 13.0 m wide. They have no drivers, so they just bounce around on their own. The rms speed of the cars is 2.50 m/s. Repeating the arguments of Pressure, Temperature, and RMS Speed, find the average force per unit length (analogous to pressure) that the cars exert on the walls. Examples: Example 1: *(a) In the deep space between galaxies, the density of atoms is as low as \(10^6\ \text{atoms/m}^3\), and the temperature is a frigid 2.7 K. What is the pressure? (b) What volume (in \(m^3\)) is occupied by 1 mol of gas? (c) If this volume is a cube, what is the length of its sides in kilometers?* Solution (a) Use the ideal gas law, where \[ PV = NkT \] \[ P = \frac{N}{V} k T = \frac{10^6}{1\ \text{m}^3} (1.38 \times 10^{-23}\ \text{J/K})(2.7\ \text{K}) \] \[ = 3.73 \times 10^{-17}\ \text{N/m}^2 = 3.7 \times 10^{-17}\ \text{N/m}^2 = \underline{3.7 \times 10^{-17}\ \text{Pa}} \] (b) Now, using the pressure found in part (a), let \(n = 1.00\ \text{mol}\). Use the ideal gas law: \[ PV = nRT \] \[ V = \frac{nRT}{P} = \frac{(1.00\ \text{mol})(8.31\ \text{J/mol·K})(2.7\ \text{K})}{3.73 \times 10^{-17}\ \text{N/m}^2} = 6.02 \times 10^{17}\ \text{m}^3 = \underline{6.0 \times 10^{17}\ \text{m}^3} \] (c) Since the volume of a cube is its length cubed: \[ L = V^{1/3} = (6.02 \times 10^{17}\ \text{m}^3)^{1/3} = 8.45 \times 10^5\ \text{m} = \underline{8.4 \times 10^2\ \text{km}} \] Example 2: *Following vigorous exercise, the body temperature of an 80.0-kg person is 40.0°C. At what rate in watts must the person transfer thermal energy to reduce the body temperature to 37.0°C in 30.0 min, assuming the body continues to produce energy at the rate of 150 W? (1 watt = 1 joule/second or 1 W = 1 J/s)* Solution First, calculate how much heat must be dissipated: \[ Q = m c_\text{human body} \Delta T = (80.0\ \text{kg})(3500\ \text{J/kg·°C})(40°C - 37°C) = 8.40 \times 10^5\ \text{J} \] Then, since power is heat divided by time, we can get the power required to produce the calculated amount of heat in 30.0 minutes: \[ P_\text{cooling} = \frac{Q}{t} = \frac{8.40 \times 10^5\ \text{J}}{(30\ \text{min})(60\ \text{s/min})} = 4.67 \times 10^2\ \text{W} \] Now, since the body continues to produce heat at a rate of 150 W, we need to add that to the required cooling power: \[ P_\text{required} = P_\text{cooling} + P_\text{body} = 467\ \text{W} + 150\ \text{W} = \underline{617\ \text{W}} \] Example 3: (a) What is the average metabolic rate in watts of a man who metabolizes 10,500 kJ of food energy in one day? (b) What is the maximum amount of work in joules he can do without breaking down fat, assuming a maximum efficiency of 20.0%? (c) Compare his work output with the daily output of a 187-W (0.250-horsepower) motor.* Solution (a) The metabolic rate is the power, so that: [ P = \frac{Q}{t} = \frac{10500\text{ kJ}}{1\text{ day}} \times \frac{1000\text{ J}}{1\text{ kJ}} \times \frac{1\text{ day}}{8.64\times10^4\text{ s}} = 122\text{ W} ] (b) Efficiency is defined to be the ratio of what we get to what we spend, or [ Eff = \frac{W}{E_{\text{in}}}, ] so we can determine the work done, knowing the efficiency: [ W = Eff \cdot E_{\text{in}} = 0.200(10500\text{ kJ}) \times \frac{1000\text{ J}}{1\text{ kJ}} = \underline{2.10\times10^6\text{ J}} ] (c) To compare with a 0.250 hp motor, we need to know how much work the motor does in one day: [ W = Pt = (0.250\text{ hp})(1\text{day}) \times \frac{746\text{ W}}{1\text{ hp}} \times \frac{8.64\times10^4\text{ s}}{1\text{day}} = 1.61\times10^7\text{ J}. ] So, the man’s work output is: [ \frac{W_{\text{motor}}}{W_{\text{man}}} ======================================= \frac{1.61\times10^7\text{ J}}{2.10\times10^6\text{ J}} = 7.67 \Rightarrow \underline{7.67\text{ times less than}} ] [ \underline{\text{the motor}}. ] Thus the motor produces 7.67 times the work done by the man. | E7: TRUE | F7: 29.5 | G7: F/L = \frac{N m v_{rms}^2}{2(L+W)} = \frac{8 \cdot 322 \cdot 2.5^2}{2(21+13)} | H7: N/m | J7: {"final_numeric":29.5,"final_formula":"F/L = \\frac{N m v_{rms}^2}{2(L+W)} = \\frac{8 \\cdot 322 \\cdot 2.5^2}{2(21+13)}","final_units":"N/m"} | K7: {'id': 'gen-1780479262-LMxe4IeVWAgNXjvvEYTS', 'object': 'chat.completion', 'created': 1780479262, 'model': 'anthropic/claude-4.7-opus-20260416', 'provider': 'Anthropic', 'system_fingerprint': None, 'service_tier': 'default', 'choices': [{'index': 0, 'logprobs': None, 'finish_reason': 'stop', 'native_finish_reason': 'end_turn', 'message': {'role': 'assistant', 'content': '{"final_numeric":29.5,"final_formula":"F/L = \\\\frac{N m v_{rms}^2}{2(L+W)} = \\\\frac{8 \\\\cdot 322 \\\\cdot 2.5^2}{2(21+13)}","final_units":"N/m"}', 'refusal': None, 'reasoning': None}}], 'usage': {'prompt_tokens': 2711, 'completion_tokens': 98, 'total_tokens': 2809, 'cost': 0.016005, 'is_byok': False, 'prompt_tokens_details': {'cached_tokens': 0, 'cache_write_tokens': 0, 'audio_tokens': 0, 'video_tokens': 0}, 'cost_details': {'upstream_inference_cost': 0.016005, 'upstream_inference_prompt_cost': 0.013555, 'upstream_inference_completions_cost': 0.00245}, 'completion_tokens_details': {'reasoning_tokens': 0, 'image_tokens': 0, 'audio_tokens': 0}}} | L7: 2711 | M7: 98 | N7: 2809 | O7: 0 | P7: =VLOOKUP(C7,problems!$A$2:$B$26,2) -> thermodynamics | Q7: =IFERROR(__xludf.DUMMYFUNCTION("INDEX(FILTER('stats2-openrouter_activity_2026'!C:C,L7='stats2-openrouter_activity_2026'!H:H,M7='stats2-openrouter_activity_2026'!I:I, B7='stats2-openrouter_activity_2026'!M:M),1)"),0.016005) -> 0.016005 | R7: =IFS( F7=VLOOKUP($C7,problems!$A$2:$G$26,6),1, True,0 ) -> 1 | S7: =IFS( G7=VLOOKUP($C7,problems!$A$2:$G$26,4),1, G7=VLOOKUP($C7,problems!$A$2:$G$26,5),1, True,0 ) -> 0 | T7: =IFS( H7=VLOOKUP($C7,problems!$A$2:$G$26,7),1, True,0 ) -> 1
A8: 2026-06-03-13-38-20 | B8: anthropic/claude-opus-4.7 | C8: 7 | D8: Какую работу в кДж совершает при изотермическом расширении водород, взятый при температуре t = 11 °С, если его объем увеличивается в 3 раза? Масса водорода m = 5 г. Examples: Example 1: *(a) In the deep space between galaxies, the density of atoms is as low as \(10^6\ \text{atoms/m}^3\), and the temperature is a frigid 2.7 K. What is the pressure? (b) What volume (in \(m^3\)) is occupied by 1 mol of gas? (c) If this volume is a cube, what is the length of its sides in kilometers?* Solution (a) Use the ideal gas law, where \[ PV = NkT \] \[ P = \frac{N}{V} k T = \frac{10^6}{1\ \text{m}^3} (1.38 \times 10^{-23}\ \text{J/K})(2.7\ \text{K}) \] \[ = 3.73 \times 10^{-17}\ \text{N/m}^2 = 3.7 \times 10^{-17}\ \text{N/m}^2 = \underline{3.7 \times 10^{-17}\ \text{Pa}} \] (b) Now, using the pressure found in part (a), let \(n = 1.00\ \text{mol}\). Use the ideal gas law: \[ PV = nRT \] \[ V = \frac{nRT}{P} = \frac{(1.00\ \text{mol})(8.31\ \text{J/mol·K})(2.7\ \text{K})}{3.73 \times 10^{-17}\ \text{N/m}^2} = 6.02 \times 10^{17}\ \text{m}^3 = \underline{6.0 \times 10^{17}\ \text{m}^3} \] (c) Since the volume of a cube is its length cubed: \[ L = V^{1/3} = (6.02 \times 10^{17}\ \text{m}^3)^{1/3} = 8.45 \times 10^5\ \text{m} = \underline{8.4 \times 10^2\ \text{km}} \] Example 2: *Following vigorous exercise, the body temperature of an 80.0-kg person is 40.0°C. At what rate in watts must the person transfer thermal energy to reduce the body temperature to 37.0°C in 30.0 min, assuming the body continues to produce energy at the rate of 150 W? (1 watt = 1 joule/second or 1 W = 1 J/s)* Solution First, calculate how much heat must be dissipated: \[ Q = m c_\text{human body} \Delta T = (80.0\ \text{kg})(3500\ \text{J/kg·°C})(40°C - 37°C) = 8.40 \times 10^5\ \text{J} \] Then, since power is heat divided by time, we can get the power required to produce the calculated amount of heat in 30.0 minutes: \[ P_\text{cooling} = \frac{Q}{t} = \frac{8.40 \times 10^5\ \text{J}}{(30\ \text{min})(60\ \text{s/min})} = 4.67 \times 10^2\ \text{W} \] Now, since the body continues to produce heat at a rate of 150 W, we need to add that to the required cooling power: \[ P_\text{required} = P_\text{cooling} + P_\text{body} = 467\ \text{W} + 150\ \text{W} = \underline{617\ \text{W}} \] Example 3: (a) What is the average metabolic rate in watts of a man who metabolizes 10,500 kJ of food energy in one day? (b) What is the maximum amount of work in joules he can do without breaking down fat, assuming a maximum efficiency of 20.0%? (c) Compare his work output with the daily output of a 187-W (0.250-horsepower) motor.* Solution (a) The metabolic rate is the power, so that: [ P = \frac{Q}{t} = \frac{10500\text{ kJ}}{1\text{ day}} \times \frac{1000\text{ J}}{1\text{ kJ}} \times \frac{1\text{ day}}{8.64\times10^4\text{ s}} = 122\text{ W} ] (b) Efficiency is defined to be the ratio of what we get to what we spend, or [ Eff = \frac{W}{E_{\text{in}}}, ] so we can determine the work done, knowing the efficiency: [ W = Eff \cdot E_{\text{in}} = 0.200(10500\text{ kJ}) \times \frac{1000\text{ J}}{1\text{ kJ}} = \underline{2.10\times10^6\text{ J}} ] (c) To compare with a 0.250 hp motor, we need to know how much work the motor does in one day: [ W = Pt = (0.250\text{ hp})(1\text{day}) \times \frac{746\text{ W}}{1\text{ hp}} \times \frac{8.64\times10^4\text{ s}}{1\text{day}} = 1.61\times10^7\text{ J}. ] So, the man’s work output is: [ \frac{W_{\text{motor}}}{W_{\text{man}}} ======================================= \frac{1.61\times10^7\text{ J}}{2.10\times10^6\text{ J}} = 7.67 \Rightarrow \underline{7.67\text{ times less than}} ] [ \underline{\text{the motor}}. ] Thus the motor produces 7.67 times the work done by the man. | E8: TRUE | F8: 16.2 | G8: A = \frac{m}{M}RT\ln\frac{V_2}{V_1} | H8: kJ | J8: {"final_numeric":16.2,"final_formula":"A = \\frac{m}{M}RT\\ln\\frac{V_2}{V_1}","final_units":"kJ"} | K8: {'id': 'gen-1780479498-djsXCCEClRIvfmTJZhZ2', 'object': 'chat.completion', 'created': 1780479498, 'model': 'anthropic/claude-4.7-opus-20260416', 'provider': 'Anthropic', 'system_fingerprint': None, 'service_tier': 'default', 'choices': [{'index': 0, 'logprobs': None, 'finish_reason': 'stop', 'native_finish_reason': 'end_turn', 'message': {'role': 'assistant', 'content': '{"final_numeric":16.2,"final_formula":"A = \\\\frac{m}{M}RT\\\\ln\\\\frac{V_2}{V_1}","final_units":"kJ"}', 'refusal': None, 'reasoning': None}}], 'usage': {'prompt_tokens': 2645, 'completion_tokens': 66, 'total_tokens': 2711, 'cost': 0.014875, 'is_byok': False, 'prompt_tokens_details': {'cached_tokens': 0, 'cache_write_tokens': 0, 'audio_tokens': 0, 'video_tokens': 0}, 'cost_details': {'upstream_inference_cost': 0.014875, 'upstream_inference_prompt_cost': 0.013225, 'upstream_inference_completions_cost': 0.00165}, 'completion_tokens_details': {'reasoning_tokens': 0, 'image_tokens': 0, 'audio_tokens': 0}}} | L8: 2645 | M8: 66 | N8: 2711 | O8: 0 | P8: =VLOOKUP(C8,problems!$A$2:$B$26,2) -> thermodynamics | Q8: =IFERROR(__xludf.DUMMYFUNCTION("INDEX(FILTER('stats2-openrouter_activity_2026'!C:C,L8='stats2-openrouter_activity_2026'!H:H,M8='stats2-openrouter_activity_2026'!I:I, B8='stats2-openrouter_activity_2026'!M:M),1)"),0.014875) -> 0.014875 | R8: =IFS( F8=VLOOKUP($C8,problems!$A$2:$G$26,6),1, True,0 ) -> 0 | S8: =IFS( G8=VLOOKUP($C8,problems!$A$2:$G$26,4),1, G8=VLOOKUP($C8,problems!$A$2:$G$26,5),1, True,0 ) -> 0 | T8: =IFS( H8=VLOOKUP($C8,problems!$A$2:$G$26,7),1, True,0 ) -> 1
A9: 2026-06-03-15-16-59 | B9: anthropic/claude-opus-4.7 | C9: 8 | D9: When an air bubble rises from the bottom to the top of a freshwater lake, its volume increases by 80%. If the temperatures at the bottom and the top of the lake are 4.0 and 10 °C, respectively, how deep is the lake? Examples: Example 1: *(a) In the deep space between galaxies, the density of atoms is as low as \(10^6\ \text{atoms/m}^3\), and the temperature is a frigid 2.7 K. What is the pressure? (b) What volume (in \(m^3\)) is occupied by 1 mol of gas? (c) If this volume is a cube, what is the length of its sides in kilometers?* Solution (a) Use the ideal gas law, where \[ PV = NkT \] \[ P = \frac{N}{V} k T = \frac{10^6}{1\ \text{m}^3} (1.38 \times 10^{-23}\ \text{J/K})(2.7\ \text{K}) \] \[ = 3.73 \times 10^{-17}\ \text{N/m}^2 = 3.7 \times 10^{-17}\ \text{N/m}^2 = \underline{3.7 \times 10^{-17}\ \text{Pa}} \] (b) Now, using the pressure found in part (a), let \(n = 1.00\ \text{mol}\). Use the ideal gas law: \[ PV = nRT \] \[ V = \frac{nRT}{P} = \frac{(1.00\ \text{mol})(8.31\ \text{J/mol·K})(2.7\ \text{K})}{3.73 \times 10^{-17}\ \text{N/m}^2} = 6.02 \times 10^{17}\ \text{m}^3 = \underline{6.0 \times 10^{17}\ \text{m}^3} \] (c) Since the volume of a cube is its length cubed: \[ L = V^{1/3} = (6.02 \times 10^{17}\ \text{m}^3)^{1/3} = 8.45 \times 10^5\ \text{m} = \underline{8.4 \times 10^2\ \text{km}} \] Example 2: *Following vigorous exercise, the body temperature of an 80.0-kg person is 40.0°C. At what rate in watts must the person transfer thermal energy to reduce the body temperature to 37.0°C in 30.0 min, assuming the body continues to produce energy at the rate of 150 W? (1 watt = 1 joule/second or 1 W = 1 J/s)* Solution First, calculate how much heat must be dissipated: \[ Q = m c_\text{human body} \Delta T = (80.0\ \text{kg})(3500\ \text{J/kg·°C})(40°C - 37°C) = 8.40 \times 10^5\ \text{J} \] Then, since power is heat divided by time, we can get the power required to produce the calculated amount of heat in 30.0 minutes: \[ P_\text{cooling} = \frac{Q}{t} = \frac{8.40 \times 10^5\ \text{J}}{(30\ \text{min})(60\ \text{s/min})} = 4.67 \times 10^2\ \text{W} \] Now, since the body continues to produce heat at a rate of 150 W, we need to add that to the required cooling power: \[ P_\text{required} = P_\text{cooling} + P_\text{body} = 467\ \text{W} + 150\ \text{W} = \underline{617\ \text{W}} \] Example 3: (a) What is the average metabolic rate in watts of a man who metabolizes 10,500 kJ of food energy in one day? (b) What is the maximum amount of work in joules he can do without breaking down fat, assuming a maximum efficiency of 20.0%? (c) Compare his work output with the daily output of a 187-W (0.250-horsepower) motor.* Solution (a) The metabolic rate is the power, so that: [ P = \frac{Q}{t} = \frac{10500\text{ kJ}}{1\text{ day}} \times \frac{1000\text{ J}}{1\text{ kJ}} \times \frac{1\text{ day}}{8.64\times10^4\text{ s}} = 122\text{ W} ] (b) Efficiency is defined to be the ratio of what we get to what we spend, or [ Eff = \frac{W}{E_{\text{in}}}, ] so we can determine the work done, knowing the efficiency: [ W = Eff \cdot E_{\text{in}} = 0.200(10500\text{ kJ}) \times \frac{1000\text{ J}}{1\text{ kJ}} = \underline{2.10\times10^6\text{ J}} ] (c) To compare with a 0.250 hp motor, we need to know how much work the motor does in one day: [ W = Pt = (0.250\text{ hp})(1\text{day}) \times \frac{746\text{ W}}{1\text{ hp}} \times \frac{8.64\times10^4\text{ s}}{1\text{day}} = 1.61\times10^7\text{ J}. ] So, the man’s work output is: [ \frac{W_{\text{motor}}}{W_{\text{man}}} ======================================= \frac{1.61\times10^7\text{ J}}{2.10\times10^6\text{ J}} = 7.67 \Rightarrow \underline{7.67\text{ times less than}} ] [ \underline{\text{the motor}}. ] Thus the motor produces 7.67 times the work done by the man. | E9: TRUE | F9: 7.69 | G9: h = \frac{P_{atm}}{\rho g}\left(\frac{V_2 T_1}{V_1 T_2} - 1\right) | H9: m | J9: {"final_numeric":7.69,"final_formula":"h = \\frac{P_{atm}}{\\rho g}\\left(\\frac{V_2 T_1}{V_1 T_2} - 1\\right)","final_units":"m"} | K9: {'id': 'gen-1780485416-H32uHHK6PCcWZjT2QpXq', 'object': 'chat.completion', 'created': 1780485416, 'model': 'anthropic/claude-4.7-opus-20260416', 'provider': 'Anthropic', 'system_fingerprint': None, 'service_tier': 'default', 'choices': [{'index': 0, 'logprobs': None, 'finish_reason': 'stop', 'native_finish_reason': 'end_turn', 'message': {'role': 'assistant', 'content': '{"final_numeric":7.69,"final_formula":"h = \\\\frac{P_{atm}}{\\\\rho g}\\\\left(\\\\frac{V_2 T_1}{V_1 T_2} - 1\\\\right)","final_units":"m"}', 'refusal': None, 'reasoning': None}}], 'usage': {'prompt_tokens': 2625, 'completion_tokens': 86, 'total_tokens': 2711, 'cost': 0.015275, 'is_byok': False, 'prompt_tokens_details': {'cached_tokens': 0, 'cache_write_tokens': 0, 'audio_tokens': 0, 'video_tokens': 0}, 'cost_details': {'upstream_inference_cost': 0.015275, 'upstream_inference_prompt_cost': 0.013125, 'upstream_inference_completions_cost': 0.00215}, 'completion_tokens_details': {'reasoning_tokens': 0, 'image_tokens': 0, 'audio_tokens': 0}}} | L9: 2625 | M9: 86 | N9: 2711 | O9: 0 | P9: =VLOOKUP(C9,problems!$A$2:$B$26,2) -> thermodynamics | Q9: =IFERROR(__xludf.DUMMYFUNCTION("INDEX(FILTER('stats2-openrouter_activity_2026'!C:C,L9='stats2-openrouter_activity_2026'!H:H,M9='stats2-openrouter_activity_2026'!I:I, B9='stats2-openrouter_activity_2026'!M:M),1)"),0.015275) -> 0.015275 | R9: =IFS( F9=VLOOKUP($C9,problems!$A$2:$G$26,6),1, True,0 ) -> 0 | S9: =IFS( G9=VLOOKUP($C9,problems!$A$2:$G$26,4),1, G9=VLOOKUP($C9,problems!$A$2:$G$26,5),1, True,0 ) -> 0 | T9: =IFS( H9=VLOOKUP($C9,problems!$A$2:$G$26,7),1, True,0 ) -> 1
A10: 2026-06-03-15-38-08 | B10: anthropic/claude-opus-4.7 | C10: 9 | D10: On a warm day when the air temperature is 30°C, a metal can is slowly cooled by adding bits of ice to liquid water in it. Condensation first appears when the can reaches 15°C. What is the relative humidity of the air? Examples: Example 1: *(a) In the deep space between galaxies, the density of atoms is as low as \(10^6\ \text{atoms/m}^3\), and the temperature is a frigid 2.7 K. What is the pressure? (b) What volume (in \(m^3\)) is occupied by 1 mol of gas? (c) If this volume is a cube, what is the length of its sides in kilometers?* Solution (a) Use the ideal gas law, where \[ PV = NkT \] \[ P = \frac{N}{V} k T = \frac{10^6}{1\ \text{m}^3} (1.38 \times 10^{-23}\ \text{J/K})(2.7\ \text{K}) \] \[ = 3.73 \times 10^{-17}\ \text{N/m}^2 = 3.7 \times 10^{-17}\ \text{N/m}^2 = \underline{3.7 \times 10^{-17}\ \text{Pa}} \] (b) Now, using the pressure found in part (a), let \(n = 1.00\ \text{mol}\). Use the ideal gas law: \[ PV = nRT \] \[ V = \frac{nRT}{P} = \frac{(1.00\ \text{mol})(8.31\ \text{J/mol·K})(2.7\ \text{K})}{3.73 \times 10^{-17}\ \text{N/m}^2} = 6.02 \times 10^{17}\ \text{m}^3 = \underline{6.0 \times 10^{17}\ \text{m}^3} \] (c) Since the volume of a cube is its length cubed: \[ L = V^{1/3} = (6.02 \times 10^{17}\ \text{m}^3)^{1/3} = 8.45 \times 10^5\ \text{m} = \underline{8.4 \times 10^2\ \text{km}} \] Example 2: *Following vigorous exercise, the body temperature of an 80.0-kg person is 40.0°C. At what rate in watts must the person transfer thermal energy to reduce the body temperature to 37.0°C in 30.0 min, assuming the body continues to produce energy at the rate of 150 W? (1 watt = 1 joule/second or 1 W = 1 J/s)* Solution First, calculate how much heat must be dissipated: \[ Q = m c_\text{human body} \Delta T = (80.0\ \text{kg})(3500\ \text{J/kg·°C})(40°C - 37°C) = 8.40 \times 10^5\ \text{J} \] Then, since power is heat divided by time, we can get the power required to produce the calculated amount of heat in 30.0 minutes: \[ P_\text{cooling} = \frac{Q}{t} = \frac{8.40 \times 10^5\ \text{J}}{(30\ \text{min})(60\ \text{s/min})} = 4.67 \times 10^2\ \text{W} \] Now, since the body continues to produce heat at a rate of 150 W, we need to add that to the required cooling power: \[ P_\text{required} = P_\text{cooling} + P_\text{body} = 467\ \text{W} + 150\ \text{W} = \underline{617\ \text{W}} \] Example 3: (a) What is the average metabolic rate in watts of a man who metabolizes 10,500 kJ of food energy in one day? (b) What is the maximum amount of work in joules he can do without breaking down fat, assuming a maximum efficiency of 20.0%? (c) Compare his work output with the daily output of a 187-W (0.250-horsepower) motor.* Solution (a) The metabolic rate is the power, so that: [ P = \frac{Q}{t} = \frac{10500\text{ kJ}}{1\text{ day}} \times \frac{1000\text{ J}}{1\text{ kJ}} \times \frac{1\text{ day}}{8.64\times10^4\text{ s}} = 122\text{ W} ] (b) Efficiency is defined to be the ratio of what we get to what we spend, or [ Eff = \frac{W}{E_{\text{in}}}, ] so we can determine the work done, knowing the efficiency: [ W = Eff \cdot E_{\text{in}} = 0.200(10500\text{ kJ}) \times \frac{1000\text{ J}}{1\text{ kJ}} = \underline{2.10\times10^6\text{ J}} ] (c) To compare with a 0.250 hp motor, we need to know how much work the motor does in one day: [ W = Pt = (0.250\text{ hp})(1\text{day}) \times \frac{746\text{ W}}{1\text{ hp}} \times \frac{8.64\times10^4\text{ s}}{1\text{day}} = 1.61\times10^7\text{ J}. ] So, the man’s work output is: [ \frac{W_{\text{motor}}}{W_{\text{man}}} ======================================= \frac{1.61\times10^7\text{ J}}{2.10\times10^6\text{ J}} = 7.67 \Rightarrow \underline{7.67\text{ times less than}} ] [ \underline{\text{the motor}}. ] Thus the motor produces 7.67 times the work done by the man. | E10: TRUE | F10: 40.2 | G10: RH = \frac{P_{sat}(15°C)}{P_{sat}(30°C)} \times 100\% = \frac{12.8}{31.8} \times 100\% | H10: % | J10: {"final_numeric":40.2,"final_formula":"RH = \\frac{P_{sat}(15°C)}{P_{sat}(30°C)} \\times 100\\% = \\frac{12.8}{31.8} \\times 100\\%","final_units":"%"} | K10: {'id': 'gen-1780486685-6W2j8gcqvdeqzo72Yl8R', 'object': 'chat.completion', 'created': 1780486685, 'model': 'anthropic/claude-4.7-opus-20260416', 'provider': 'Anthropic', 'system_fingerprint': None, 'service_tier': 'default', 'choices': [{'index': 0, 'logprobs': None, 'finish_reason': 'stop', 'native_finish_reason': 'end_turn', 'message': {'role': 'assistant', 'content': '{"final_numeric":40.2,"final_formula":"RH = \\\\frac{P_{sat}(15°C)}{P_{sat}(30°C)} \\\\times 100\\\\% = \\\\frac{12.8}{31.8} \\\\times 100\\\\%","final_units":"%"}', 'refusal': None, 'reasoning': None}}], 'usage': {'prompt_tokens': 2621, 'completion_tokens': 96, 'total_tokens': 2717, 'cost': 0.015505, 'is_byok': False, 'prompt_tokens_details': {'cached_tokens': 0, 'cache_write_tokens': 0, 'audio_tokens': 0, 'video_tokens': 0}, 'cost_details': {'upstream_inference_cost': 0.015505, 'upstream_inference_prompt_cost': 0.013105, 'upstream_inference_completions_cost': 0.0024}, 'completion_tokens_details': {'reasoning_tokens': 0, 'image_tokens': 0, 'audio_tokens': 0}}} | L10: 2621 | M10: 96 | N10: 2717 | O10: 0 | P10: =VLOOKUP(C10,problems!$A$2:$B$26,2) -> thermodynamics | Q10: =IFERROR(__xludf.DUMMYFUNCTION("INDEX(FILTER('stats2-openrouter_activity_2026'!C:C,L10='stats2-openrouter_activity_2026'!H:H,M10='stats2-openrouter_activity_2026'!I:I, B10='stats2-openrouter_activity_2026'!M:M),1)"),0.015505) -> 0.015505 | R10: =IFS( F10=VLOOKUP($C10,problems!$A$2:$G$26,6),1, True,0 ) -> 0 | S10: =IFS( G10=VLOOKUP($C10,problems!$A$2:$G$26,4),1, G10=VLOOKUP($C10,problems!$A$2:$G$26,5),1, True,0 ) -> 0 | T10: =IFS( H10=VLOOKUP($C10,problems!$A$2:$G$26,7),1, True,0 ) -> 1
A11: 2026-06-03-15-41-37 | B11: anthropic/claude-opus-4.7 | C11: 10 | D11: Газ, занимающий объем V_{1} = 10 л при давлении р_{1} = 2*10^5 Па, расширяется изотермически до объема V_{2} = 28 л. Какую работу в кДж он при этом совершает? Examples: Example 1: *(a) In the deep space between galaxies, the density of atoms is as low as \(10^6\ \text{atoms/m}^3\), and the temperature is a frigid 2.7 K. What is the pressure? (b) What volume (in \(m^3\)) is occupied by 1 mol of gas? (c) If this volume is a cube, what is the length of its sides in kilometers?* Solution (a) Use the ideal gas law, where \[ PV = NkT \] \[ P = \frac{N}{V} k T = \frac{10^6}{1\ \text{m}^3} (1.38 \times 10^{-23}\ \text{J/K})(2.7\ \text{K}) \] \[ = 3.73 \times 10^{-17}\ \text{N/m}^2 = 3.7 \times 10^{-17}\ \text{N/m}^2 = \underline{3.7 \times 10^{-17}\ \text{Pa}} \] (b) Now, using the pressure found in part (a), let \(n = 1.00\ \text{mol}\). Use the ideal gas law: \[ PV = nRT \] \[ V = \frac{nRT}{P} = \frac{(1.00\ \text{mol})(8.31\ \text{J/mol·K})(2.7\ \text{K})}{3.73 \times 10^{-17}\ \text{N/m}^2} = 6.02 \times 10^{17}\ \text{m}^3 = \underline{6.0 \times 10^{17}\ \text{m}^3} \] (c) Since the volume of a cube is its length cubed: \[ L = V^{1/3} = (6.02 \times 10^{17}\ \text{m}^3)^{1/3} = 8.45 \times 10^5\ \text{m} = \underline{8.4 \times 10^2\ \text{km}} \] Example 2: *Following vigorous exercise, the body temperature of an 80.0-kg person is 40.0°C. At what rate in watts must the person transfer thermal energy to reduce the body temperature to 37.0°C in 30.0 min, assuming the body continues to produce energy at the rate of 150 W? (1 watt = 1 joule/second or 1 W = 1 J/s)* Solution First, calculate how much heat must be dissipated: \[ Q = m c_\text{human body} \Delta T = (80.0\ \text{kg})(3500\ \text{J/kg·°C})(40°C - 37°C) = 8.40 \times 10^5\ \text{J} \] Then, since power is heat divided by time, we can get the power required to produce the calculated amount of heat in 30.0 minutes: \[ P_\text{cooling} = \frac{Q}{t} = \frac{8.40 \times 10^5\ \text{J}}{(30\ \text{min})(60\ \text{s/min})} = 4.67 \times 10^2\ \text{W} \] Now, since the body continues to produce heat at a rate of 150 W, we need to add that to the required cooling power: \[ P_\text{required} = P_\text{cooling} + P_\text{body} = 467\ \text{W} + 150\ \text{W} = \underline{617\ \text{W}} \] Example 3: (a) What is the average metabolic rate in watts of a man who metabolizes 10,500 kJ of food energy in one day? (b) What is the maximum amount of work in joules he can do without breaking down fat, assuming a maximum efficiency of 20.0%? (c) Compare his work output with the daily output of a 187-W (0.250-horsepower) motor.* Solution (a) The metabolic rate is the power, so that: [ P = \frac{Q}{t} = \frac{10500\text{ kJ}}{1\text{ day}} \times \frac{1000\text{ J}}{1\text{ kJ}} \times \frac{1\text{ day}}{8.64\times10^4\text{ s}} = 122\text{ W} ] (b) Efficiency is defined to be the ratio of what we get to what we spend, or [ Eff = \frac{W}{E_{\text{in}}}, ] so we can determine the work done, knowing the efficiency: [ W = Eff \cdot E_{\text{in}} = 0.200(10500\text{ kJ}) \times \frac{1000\text{ J}}{1\text{ kJ}} = \underline{2.10\times10^6\text{ J}} ] (c) To compare with a 0.250 hp motor, we need to know how much work the motor does in one day: [ W = Pt = (0.250\text{ hp})(1\text{day}) \times \frac{746\text{ W}}{1\text{ hp}} \times \frac{8.64\times10^4\text{ s}}{1\text{day}} = 1.61\times10^7\text{ J}. ] So, the man’s work output is: [ \frac{W_{\text{motor}}}{W_{\text{man}}} ======================================= \frac{1.61\times10^7\text{ J}}{2.10\times10^6\text{ J}} = 7.67 \Rightarrow \underline{7.67\text{ times less than}} ] [ \underline{\text{the motor}}. ] Thus the motor produces 7.67 times the work done by the man. | E11: TRUE | F11: 2.06 | G11: A = p_1 V_1 \ln\frac{V_2}{V_1} | H11: kJ | J11: {"final_numeric":2.06,"final_formula":"A = p_1 V_1 \\ln\\frac{V_2}{V_1}","final_units":"kJ"} | K11: {'id': 'gen-1780486895-VI2O8x2deEmhB6f1wB8I', 'object': 'chat.completion', 'created': 1780486895, 'model': 'anthropic/claude-4.7-opus-20260416', 'provider': 'Anthropic', 'system_fingerprint': None, 'service_tier': 'default', 'choices': [{'index': 0, 'logprobs': None, 'finish_reason': 'stop', 'native_finish_reason': 'end_turn', 'message': {'role': 'assistant', 'content': '{"final_numeric":2.06,"final_formula":"A = p_1 V_1 \\\\ln\\\\frac{V_2}{V_1}","final_units":"kJ"}', 'refusal': None, 'reasoning': None}}], 'usage': {'prompt_tokens': 2626, 'completion_tokens': 62, 'total_tokens': 2688, 'cost': 0.01468, 'is_byok': False, 'prompt_tokens_details': {'cached_tokens': 0, 'cache_write_tokens': 0, 'audio_tokens': 0, 'video_tokens': 0}, 'cost_details': {'upstream_inference_cost': 0.01468, 'upstream_inference_prompt_cost': 0.01313, 'upstream_inference_completions_cost': 0.00155}, 'completion_tokens_details': {'reasoning_tokens': 0, 'image_tokens': 0, 'audio_tokens': 0}}} | L11: 2626 | M11: 62 | N11: 2688 | O11: 0 | P11: =VLOOKUP(C11,problems!$A$2:$B$26,2) -> thermodynamics | Q11: =IFERROR(__xludf.DUMMYFUNCTION("INDEX(FILTER('stats2-openrouter_activity_2026'!C:C,L11='stats2-openrouter_activity_2026'!H:H,M11='stats2-openrouter_activity_2026'!I:I, B11='stats2-openrouter_activity_2026'!M:M),1)"),0.01468) -> 0.01468 | R11: =IFS( F11=VLOOKUP($C11,problems!$A$2:$G$26,6),1, True,0 ) -> 1 | S11: =IFS( G11=VLOOKUP($C11,problems!$A$2:$G$26,4),1, G11=VLOOKUP($C11,problems!$A$2:$G$26,5),1, True,0 ) -> 0 | T11: =IFS( H11=VLOOKUP($C11,problems!$A$2:$G$26,7),1, True,0 ) -> 1
