Workbook

Sheet physics_results
A1: datetime | B1: ai_model | C1: statement_row_id | D1: statement | E1: ok | F1: final_numeric | G1: final_formula | H1: final_units | I1: error | J1: raw_response_text | K1: full_api_response | L1: prompt_tokens | M1: completion_tokens | N1: total_tokens | O1: prompt_version | P1: topic | Q1: cost | R1: is_correct_number | S1: is_correct_formula | T1: is_correct_units
A2: 2026-06-03-17-05-55 | B2: anthropic/claude-opus-4.7 | C2: 1 | D2: Дано: l = 2 м — расстояние, которое частица пролетает равномерно a = 5*10^5 м/с^2 — ускорение торможения, направлено против движения. Найти: v - скорость частицы, при которой полное время движения от вылета до остановки минимально в м/с | E2: TRUE | F2: 1000 | G2: v=\sqrt{la} | H2: m/s | J2: Total time: t = l/v + v/a. Minimize: dt/dv = -l/v² + 1/a = 0, v = √(la) = √(2·5×10⁵) = √10⁶ = 1000 m/s. {"final_numeric":1000,"final_formula":"v=\\sqrt{la}","final_units":"m/s"} | K2: {'id': 'gen-1780491953-Jx9tZvgl19ST4QF2NLyV', 'object': 'chat.completion', 'created': 1780491953, 'model': 'anthropic/claude-4.7-opus-20260416', 'provider': 'Anthropic', 'system_fingerprint': None, 'service_tier': 'default', 'choices': [{'index': 0, 'logprobs': None, 'finish_reason': 'stop', 'native_finish_reason': 'end_turn', 'message': {'role': 'assistant', 'content': 'Total time: t = l/v + v/a. Minimize: dt/dv = -l/v² + 1/a = 0, v = √(la) = √(2·5×10⁵) = √10⁶ = 1000 m/s.\n\n{"final_numeric":1000,"final_formula":"v=\\\\sqrt{la}","final_units":"m/s"}', 'refusal': None, 'reasoning': None}}], 'usage': {'prompt_tokens': 814, 'completion_tokens': 118, 'total_tokens': 932, 'cost': 0.00702, 'is_byok': False, 'prompt_tokens_details': {'cached_tokens': 0, 'cache_write_tokens': 0, 'audio_tokens': 0, 'video_tokens': 0}, 'cost_details': {'upstream_inference_cost': 0.00702, 'upstream_inference_prompt_cost': 0.00407, 'upstream_inference_completions_cost': 0.00295}, 'completion_tokens_details': {'reasoning_tokens': 0, 'image_tokens': 0, 'audio_tokens': 0}}} | L2: 814 | M2: 118 | N2: 932 | O2: 0 | P2: =VLOOKUP(C2,problems!$A$2:$B$26,2) -> mechanics | Q2: =IFERROR(__xludf.DUMMYFUNCTION("INDEX(FILTER('stats2-openrouter_activity_2026'!C:C,L2='stats2-openrouter_activity_2026'!H:H,M2='stats2-openrouter_activity_2026'!I:I, B2='stats2-openrouter_activity_2026'!M:M),1)"),0.00702) -> 0.00702 | R2: =IFS( F2=VLOOKUP($C2,problems!$A$2:$G$26,6),1, True,0 ) -> 1 | S2: =IFS( G2=VLOOKUP($C2,problems!$A$2:$G$26,4),1, G2=VLOOKUP($C2,problems!$A$2:$G$26,5),1, True,0 ) -> 0 | T2: =IFS( H2=VLOOKUP($C2,problems!$A$2:$G$26,7),1, True,0 ) -> 1
A3: 2026-06-03-17-06-06 | B3: anthropic/claude-opus-4.7 | C3: 2 | D3: Дано: x = At+Bt^3 — закон движения точки по оси x. A = 6 м/с B = -0.125 м/с^3 t_1 = 2 с t_2 = 6 с Найти: v_{ср} — средняя скорость точки за интервал времени от t_{1} до t_{2}​ в м/с | E3: TRUE | F3: -0.5 | G3: v_{ср}=\frac{A(t_2-t_1)+B(t_2^3-t_1^3)}{t_2-t_1} | H3: m/s | J3: x(2)=12-1=11, x(6)=36-27=9. Δx=-2, Δt=4, v=-0.5 {"final_numeric":-0.5,"final_formula":"v_{ср}=\\frac{A(t_2-t_1)+B(t_2^3-t_1^3)}{t_2-t_1}","final_units":"m/s"} | K3: {'id': 'gen-1780491964-ZmksvvRTv0CWKVn04qT8', 'object': 'chat.completion', 'created': 1780491964, 'model': 'anthropic/claude-4.7-opus-20260416', 'provider': 'Anthropic', 'system_fingerprint': None, 'service_tier': 'default', 'choices': [{'index': 0, 'logprobs': None, 'finish_reason': 'stop', 'native_finish_reason': 'end_turn', 'message': {'role': 'assistant', 'content': 'x(2)=12-1=11, x(6)=36-27=9. Δx=-2, Δt=4, v=-0.5\n\n{"final_numeric":-0.5,"final_formula":"v_{ср}=\\\\frac{A(t_2-t_1)+B(t_2^3-t_1^3)}{t_2-t_1}","final_units":"m/s"}', 'refusal': None, 'reasoning': None}}], 'usage': {'prompt_tokens': 829, 'completion_tokens': 124, 'total_tokens': 953, 'cost': 0.007245, 'is_byok': False, 'prompt_tokens_details': {'cached_tokens': 0, 'cache_write_tokens': 0, 'audio_tokens': 0, 'video_tokens': 0}, 'cost_details': {'upstream_inference_cost': 0.007245, 'upstream_inference_prompt_cost': 0.004145, 'upstream_inference_completions_cost': 0.0031}, 'completion_tokens_details': {'reasoning_tokens': 0, 'image_tokens': 0, 'audio_tokens': 0}}} | L3: 829 | M3: 124 | N3: 953 | O3: 0 | P3: =VLOOKUP(C3,problems!$A$2:$B$26,2) -> mechanics | Q3: =IFERROR(__xludf.DUMMYFUNCTION("INDEX(FILTER('stats2-openrouter_activity_2026'!C:C,L3='stats2-openrouter_activity_2026'!H:H,M3='stats2-openrouter_activity_2026'!I:I, B3='stats2-openrouter_activity_2026'!M:M),1)"),0.007245) -> 0.007245 | R3: =IFS( F3=VLOOKUP($C3,problems!$A$2:$G$26,6),1, True,0 ) -> 1 | S3: =IFS( G3=VLOOKUP($C3,problems!$A$2:$G$26,4),1, G3=VLOOKUP($C3,problems!$A$2:$G$26,5),1, True,0 ) -> 0 | T3: =IFS( H3=VLOOKUP($C3,problems!$A$2:$G$26,7),1, True,0 ) -> 1
A4: 2026-06-03-17-06-51 | B4: anthropic/claude-opus-4.7 | C4: 3 | D4: Given: v_{1} = 80 km/h — east truck's speed v_{2} = 50 km/h — north car's speed d = 32 km — distance from the truck to the intersection at the initial moment. Find: t — the time in hours after this moment when the vehicles will be closest to each other. | E4: TRUE | F4: 0.2876 | G4: t = \frac{v_1 d}{v_1^2 + v_2^2} | H4: h | J4: Truck position: x = d - v1·t (approaching intersection from west, going east). Car at intersection going north: y = v2·t. Distance² = (d-v1t)² + (v2t)² d/dt: -2v1(d-v1t) + 2v2²t = 0 t = v1·d/(v1²+v2²) = 80·32/(6400+2500) = 2560/8900 ≈ 0.2876 h {"final_numeric": 0.2876,"final_formula": "t = \\frac{v_1 d}{v_1^2 + v_2^2}","final_units": "h"} | K4: {'id': 'gen-1780492008-tVEKGWpV6fuFFIww2pcl', 'object': 'chat.completion', 'created': 1780492008, 'model': 'anthropic/claude-4.7-opus-20260416', 'provider': 'Anthropic', 'system_fingerprint': None, 'service_tier': 'default', 'choices': [{'index': 0, 'logprobs': None, 'finish_reason': 'stop', 'native_finish_reason': 'end_turn', 'message': {'role': 'assistant', 'content': 'Truck position: x = d - v1·t (approaching intersection from west, going east). Car at intersection going north: y = v2·t.\n\nDistance² = (d-v1t)² + (v2t)²\nd/dt: -2v1(d-v1t) + 2v2²t = 0\nt = v1·d/(v1²+v2²) = 80·32/(6400+2500) = 2560/8900 ≈ 0.2876 h\n\n{"final_numeric": 0.2876,"final_formula": "t = \\\\frac{v_1 d}{v_1^2 + v_2^2}","final_units": "h"}', 'refusal': None, 'reasoning': None}}], 'usage': {'prompt_tokens': 813, 'completion_tokens': 201, 'total_tokens': 1014, 'cost': 0.00909, 'is_byok': False, 'prompt_tokens_details': {'cached_tokens': 0, 'cache_write_tokens': 0, 'audio_tokens': 0, 'video_tokens': 0}, 'cost_details': {'upstream_inference_cost': 0.00909, 'upstream_inference_prompt_cost': 0.004065, 'upstream_inference_completions_cost': 0.005025}, 'completion_tokens_details': {'reasoning_tokens': 0, 'image_tokens': 0, 'audio_tokens': 0}}} | L4: 813 | M4: 201 | N4: 1014 | O4: 0 | P4: =VLOOKUP(C4,problems!$A$2:$B$26,2) -> mechanics | Q4: =IFERROR(__xludf.DUMMYFUNCTION("INDEX(FILTER('stats2-openrouter_activity_2026'!C:C,L4='stats2-openrouter_activity_2026'!H:H,M4='stats2-openrouter_activity_2026'!I:I, B4='stats2-openrouter_activity_2026'!M:M),1)"),0.00909) -> 0.00909 | R4: =IFS( F4=VLOOKUP($C4,problems!$A$2:$G$26,6),1, True,0 ) -> 0 | S4: =IFS( G4=VLOOKUP($C4,problems!$A$2:$G$26,4),1, G4=VLOOKUP($C4,problems!$A$2:$G$26,5),1, True,0 ) -> 0 | T4: =IFS( H4=VLOOKUP($C4,problems!$A$2:$G$26,7),1, True,0 ) -> 1
A5: 2026-06-03-17-08-43 | B5: anthropic/claude-opus-4.7 | C5: 4 | D5: Дано: х = а_1 + b_{1}*t + y_{1}*t^2 — закон движения точки по оси x. y = α_2 + b_{2}*t + y_{2}*t^2 — закон движения точки по оси y. b_1 = b_2 = 1 м/с y_1 = -1 м/c^2 y_2 = 2 м/с^2 t = 1 с a — ускорение материальной точки Найти: \phi — угол между скоростью и ускорением в момент времени t в градусах | E5: TRUE | F5: 15.26 | G5: \phi = \arccos\left(\frac{v_x a_x + v_y a_y}{\sqrt{v_x^2+v_y^2}\sqrt{a_x^2+a_y^2}}\right) | H5: deg | J5: vx = b1 + 2γ1 t = 1 + 2(-1)(1) = -1 vy = b2 + 2γ2 t = 1 + 2(2)(1) = 5 ax = 2γ1 = -2 ay = 2γ2 = 4 v·a = (-1)(-2) + (5)(4) = 2 + 20 = 22 |v| = √(1+25) = √26 |a| = √(4+16) = √20 cos φ = 22/(√26·√20) = 22/√520 ≈ 22/22.804 ≈ 0.9648 φ ≈ 15.26° {"final_numeric": 15.26, "final_formula": "\\phi = \\arccos\\left(\\frac{v_x a_x + v_y a_y}{\\sqrt{v_x^2+v_y^2}\\sqrt{a_x^2+a_y^2}}\\right)", "final_units": "deg"} | K5: {'id': 'gen-1780492119-iuqmf3fE0BVXrgaY2BKx', 'object': 'chat.completion', 'created': 1780492119, 'model': 'anthropic/claude-4.7-opus-20260416', 'provider': 'Anthropic', 'system_fingerprint': None, 'service_tier': 'default', 'choices': [{'index': 0, 'logprobs': None, 'finish_reason': 'stop', 'native_finish_reason': 'end_turn', 'message': {'role': 'assistant', 'content': 'vx = b1 + 2γ1 t = 1 + 2(-1)(1) = -1\nvy = b2 + 2γ2 t = 1 + 2(2)(1) = 5\nax = 2γ1 = -2\nay = 2γ2 = 4\n\nv·a = (-1)(-2) + (5)(4) = 2 + 20 = 22\n|v| = √(1+25) = √26\n|a| = √(4+16) = √20\n\ncos φ = 22/(√26·√20) = 22/√520 ≈ 22/22.804 ≈ 0.9648\nφ ≈ 15.26°\n\n{"final_numeric": 15.26, "final_formula": "\\\\phi = \\\\arccos\\\\left(\\\\frac{v_x a_x + v_y a_y}{\\\\sqrt{v_x^2+v_y^2}\\\\sqrt{a_x^2+a_y^2}}\\\\right)", "final_units": "deg"}', 'refusal': None, 'reasoning': None}}], 'usage': {'prompt_tokens': 890, 'completion_tokens': 315, 'total_tokens': 1205, 'cost': 0.012325, 'is_byok': False, 'prompt_tokens_details': {'cached_tokens': 0, 'cache_write_tokens': 0, 'audio_tokens': 0, 'video_tokens': 0}, 'cost_details': {'upstream_inference_cost': 0.012325, 'upstream_inference_prompt_cost': 0.00445, 'upstream_inference_completions_cost': 0.007875}, 'completion_tokens_details': {'reasoning_tokens': 0, 'image_tokens': 0, 'audio_tokens': 0}}} | L5: 890 | M5: 315 | N5: 1205 | O5: 0 | P5: =VLOOKUP(C5,problems!$A$2:$B$26,2) -> mechanics | Q5: =IFERROR(__xludf.DUMMYFUNCTION("INDEX(FILTER('stats2-openrouter_activity_2026'!C:C,L5='stats2-openrouter_activity_2026'!H:H,M5='stats2-openrouter_activity_2026'!I:I, B5='stats2-openrouter_activity_2026'!M:M),1)"),0.012325) -> 0.012325 | R5: =IFS( F5=VLOOKUP($C5,problems!$A$2:$G$26,6),1, True,0 ) -> 0 | S5: =IFS( G5=VLOOKUP($C5,problems!$A$2:$G$26,4),1, G5=VLOOKUP($C5,problems!$A$2:$G$26,5),1, True,0 ) -> 0 | T5: =IFS( H5=VLOOKUP($C5,problems!$A$2:$G$26,7),1, True,0 ) -> 0
A6: 2026-06-03-17-12-10 | B6: anthropic/claude-opus-4.7 | C6: 5 | D6: Given: A crate is moving across a rough floor surface. If no external pushing force is applied, friction slows the crate down until it stops. m = 50 kg — mass of the crate. v_0 = 8 m/s — initial speed of the crate. v = 0 m/s — final speed of the crate, because it comes to rest. \Delta t = 10 s — time during which the crate comes to rest. Find: P — the rate at which the frictional force takes energy away from the crate, in J/s. | E6: TRUE | F6: 160 | G6: P=\frac{\frac{1}{2}mv_0^2}{\Delta t} | H6: W | J6: {"final_numeric":160,"final_formula":"P=\\frac{\\frac{1}{2}mv_0^2}{\\Delta t}","final_units":"W"} | K6: {'id': 'gen-1780492329-Btupi8y2iJRiRMSFeEV4', 'object': 'chat.completion', 'created': 1780492329, 'model': 'anthropic/claude-4.7-opus-20260416', 'provider': 'Anthropic', 'system_fingerprint': None, 'service_tier': 'default', 'choices': [{'index': 0, 'logprobs': None, 'finish_reason': 'stop', 'native_finish_reason': 'end_turn', 'message': {'role': 'assistant', 'content': '{"final_numeric":160,"final_formula":"P=\\\\frac{\\\\frac{1}{2}mv_0^2}{\\\\Delta t}","final_units":"W"}', 'refusal': None, 'reasoning': None}}], 'usage': {'prompt_tokens': 878, 'completion_tokens': 62, 'total_tokens': 940, 'cost': 0.00594, 'is_byok': False, 'prompt_tokens_details': {'cached_tokens': 0, 'cache_write_tokens': 0, 'audio_tokens': 0, 'video_tokens': 0}, 'cost_details': {'upstream_inference_cost': 0.00594, 'upstream_inference_prompt_cost': 0.00439, 'upstream_inference_completions_cost': 0.00155}, 'completion_tokens_details': {'reasoning_tokens': 0, 'image_tokens': 0, 'audio_tokens': 0}}} | L6: 878 | M6: 62 | N6: 940 | O6: 0 | P6: =VLOOKUP(C6,problems!$A$2:$B$26,2) -> mechanics | Q6: =IFERROR(__xludf.DUMMYFUNCTION("INDEX(FILTER('stats2-openrouter_activity_2026'!C:C,L6='stats2-openrouter_activity_2026'!H:H,M6='stats2-openrouter_activity_2026'!I:I, B6='stats2-openrouter_activity_2026'!M:M),1)"),0.00594) -> 0.00594 | R6: =IFS( F6=VLOOKUP($C6,problems!$A$2:$G$26,6),1, True,0 ) -> 1 | S6: =IFS( G6=VLOOKUP($C6,problems!$A$2:$G$26,4),1, G6=VLOOKUP($C6,problems!$A$2:$G$26,5),1, True,0 ) -> 0 | T6: =IFS( H6=VLOOKUP($C6,problems!$A$2:$G$26,7),1, True,0 ) -> 0
A7: 2026-06-03-17-13-32 | B7: anthropic/claude-opus-4.7 | C7: 6 | D7: Given: N = 8 — number of bumper cars. m = 322 kg — mass of each bumper car. L = 21 m — length of the room. W = 13 m — width of the room. v_rms = 2.5 m/s — rms speed of the bumper cars. The cars move randomly and bounce off the walls, similar to gas particles. Find: P — the average force per unit length that the cars exert on the walls, in N/m. | E7: TRUE | F7: 29.49 | G7: P = \frac{N m v_{rms}^2}{2 L W} | H7: N/m | J7: Using 2D gas analogy: P*perimeter... actually pressure in 2D: P = N m v_rms² / (2A), force per unit length on walls. For 2D ideal gas: PA = N m v²/2 where P is force per length. Wait, let me think. In 2D, kinetic energy = N·(1/2)m v_rms² = (2/2)NkT = NkT (2 DOF). Pressure (force/length): P·A = NkT, so P = NkT/A = N m v_rms²/(2A). A = 21·13 = 273 m² P = 8 · 322 · 6.25 / (2·273) = 16100/546 = 29.487 N/m {"final_numeric": 29.49, "final_formula": "P = \\frac{N m v_{rms}^2}{2 L W}", "final_units": "N/m"} | K7: {'id': 'gen-1780492407-dPkSdFtFf5BkrUfDXp0o', 'object': 'chat.completion', 'created': 1780492407, 'model': 'anthropic/claude-4.7-opus-20260416', 'provider': 'Anthropic', 'system_fingerprint': None, 'service_tier': 'default', 'choices': [{'index': 0, 'logprobs': None, 'finish_reason': 'stop', 'native_finish_reason': 'end_turn', 'message': {'role': 'assistant', 'content': 'Using 2D gas analogy: P*perimeter... actually pressure in 2D: P = N m v_rms² / (2A), force per unit length on walls.\n\nFor 2D ideal gas: PA = N m v²/2 where P is force per length. Wait, let me think.\n\nIn 2D, kinetic energy = N·(1/2)m v_rms² = (2/2)NkT = NkT (2 DOF). Pressure (force/length): P·A = NkT, so P = NkT/A = N m v_rms²/(2A).\n\nA = 21·13 = 273 m²\nP = 8 · 322 · 6.25 / (2·273) = 16100/546 = 29.487 N/m\n\n{"final_numeric": 29.49, "final_formula": "P = \\\\frac{N m v_{rms}^2}{2 L W}", "final_units": "N/m"}', 'refusal': None, 'reasoning': None}}], 'usage': {'prompt_tokens': 858, 'completion_tokens': 284, 'total_tokens': 1142, 'cost': 0.01139, 'is_byok': False, 'prompt_tokens_details': {'cached_tokens': 0, 'cache_write_tokens': 0, 'audio_tokens': 0, 'video_tokens': 0}, 'cost_details': {'upstream_inference_cost': 0.01139, 'upstream_inference_prompt_cost': 0.00429, 'upstream_inference_completions_cost': 0.0071}, 'completion_tokens_details': {'reasoning_tokens': 0, 'image_tokens': 0, 'audio_tokens': 0}}} | L7: 858 | M7: 284 | N7: 1142 | O7: 0 | P7: =VLOOKUP(C7,problems!$A$2:$B$26,2) -> thermodynamics | Q7: =IFERROR(__xludf.DUMMYFUNCTION("INDEX(FILTER('stats2-openrouter_activity_2026'!C:C,L7='stats2-openrouter_activity_2026'!H:H,M7='stats2-openrouter_activity_2026'!I:I, B7='stats2-openrouter_activity_2026'!M:M),1)"),0.01139) -> 0.01139 | R7: =IFS( F7=VLOOKUP($C7,problems!$A$2:$G$26,6),1, True,0 ) -> 0 | S7: =IFS( G7=VLOOKUP($C7,problems!$A$2:$G$26,4),1, G7=VLOOKUP($C7,problems!$A$2:$G$26,5),1, True,0 ) -> 0 | T7: =IFS( H7=VLOOKUP($C7,problems!$A$2:$G$26,7),1, True,0 ) -> 1
A8: 2026-06-03-17-14-59 | B8: anthropic/claude-opus-4.7 | C8: 7 | D8: Дано: t = 11∘C — температура водорода. m = 5 г — масса водорода. V_2/V_1 = 3 — объем водорода увеличился в 3 раза. Найти: A — работу, совершенную водородом при изотермическом расширении, в кДж. | E8: TRUE | F8: 6485 | G8: A = \frac{m}{M} R T \ln\frac{V_2}{V_1} | H8: J | J8: A = (m/M)RT ln(V2/V1) = (0.005/0.002)(8.314)(284) ln3 = 2.5 × 8.314 × 284 × 1.0986 = 2.5 × 8.314 × 312.0 ≈ 6486 J ≈ 6.49 kJ Wait, let me recompute: 8.314 × 284 = 2361.18; × 1.0986 = 2594.0; × 2.5 = 6485 J { "final_numeric": 6485, "final_formula": "A = \\frac{m}{M} R T \\ln\\frac{V_2}{V_1}", "final_units": "J" } | K8: {'id': 'gen-1780492495-RUCMwoFO5hyl7WGzePxC', 'object': 'chat.completion', 'created': 1780492495, 'model': 'anthropic/claude-4.7-opus-20260416', 'provider': 'Anthropic', 'system_fingerprint': None, 'service_tier': 'default', 'choices': [{'index': 0, 'logprobs': None, 'finish_reason': 'stop', 'native_finish_reason': 'end_turn', 'message': {'role': 'assistant', 'content': 'A = (m/M)RT ln(V2/V1) = (0.005/0.002)(8.314)(284) ln3\n= 2.5 × 8.314 × 284 × 1.0986\n= 2.5 × 8.314 × 312.0 ≈ 6486 J ≈ 6.49 kJ\n\nWait, let me recompute: 8.314 × 284 = 2361.18; × 1.0986 = 2594.0; × 2.5 = 6485 J\n\n{\n "final_numeric": 6485,\n "final_formula": "A = \\\\frac{m}{M} R T \\\\ln\\\\frac{V_2}{V_1}",\n "final_units": "J"\n}', 'refusal': None, 'reasoning': None}}], 'usage': {'prompt_tokens': 810, 'completion_tokens': 228, 'total_tokens': 1038, 'cost': 0.00975, 'is_byok': False, 'prompt_tokens_details': {'cached_tokens': 0, 'cache_write_tokens': 0, 'audio_tokens': 0, 'video_tokens': 0}, 'cost_details': {'upstream_inference_cost': 0.00975, 'upstream_inference_prompt_cost': 0.00405, 'upstream_inference_completions_cost': 0.0057}, 'completion_tokens_details': {'reasoning_tokens': 0, 'image_tokens': 0, 'audio_tokens': 0}}} | L8: 810 | M8: 228 | N8: 1038 | O8: 0 | P8: =VLOOKUP(C8,problems!$A$2:$B$26,2) -> thermodynamics | Q8: =IFERROR(__xludf.DUMMYFUNCTION("INDEX(FILTER('stats2-openrouter_activity_2026'!C:C,L8='stats2-openrouter_activity_2026'!H:H,M8='stats2-openrouter_activity_2026'!I:I, B8='stats2-openrouter_activity_2026'!M:M),1)"),0.00975) -> 0.00975 | R8: =IFS( F8=VLOOKUP($C8,problems!$A$2:$G$26,6),1, True,0 ) -> 0 | S8: =IFS( G8=VLOOKUP($C8,problems!$A$2:$G$26,4),1, G8=VLOOKUP($C8,problems!$A$2:$G$26,5),1, True,0 ) -> 0 | T8: =IFS( H8=VLOOKUP($C8,problems!$A$2:$G$26,7),1, True,0 ) -> 0
A9: 2026-06-03-17-17-45 | B9: anthropic/claude-opus-4.7 | C9: 8 | D9: Find: An air bubble rises from the bottom to the top of a freshwater lake. V_2/V_1 = 1.8 — the bubble’s volume increases by 80%. T_1 = 4∘C — temperature at the bottom of the lake. T_2 = 10∘C — temperature at the top of the lake. p_0 = 1.01 * 10^5 Pa — atmospheric pressure at the surface of the lake. p = 1000 kg/m^3 — density of freshwater. Find: h — the depth of the lake, in meters. | E9: TRUE | F9: 7.85 | G9: h = \frac{p_0}{\rho g}\left(\frac{V_2 T_1}{V_1 T_2} - 1\right) | H9: m | J9: p1V1/T1 = p2V2/T2 p1 = p2(V2/V1)(T1/T2) = 1.01e5 * 1.8 * 277/283 = 1.01e5 * 1.8 * 0.97881 = 1.7795e5 p1 - p0 = ρgh h = (1.7795e5 - 1.01e5)/(1000*9.8) = 76950/9800 = 7.852 m {"final_numeric": 7.85, "final_formula": "h = \\frac{p_0}{\\rho g}\\left(\\frac{V_2 T_1}{V_1 T_2} - 1\\right)", "final_units": "m"} | K9: {'id': 'gen-1780492661-aFcCv8XjiqdOFgOTlFWU', 'object': 'chat.completion', 'created': 1780492661, 'model': 'anthropic/claude-4.7-opus-20260416', 'provider': 'Anthropic', 'system_fingerprint': None, 'service_tier': 'default', 'choices': [{'index': 0, 'logprobs': None, 'finish_reason': 'stop', 'native_finish_reason': 'end_turn', 'message': {'role': 'assistant', 'content': 'p1V1/T1 = p2V2/T2\np1 = p2(V2/V1)(T1/T2) = 1.01e5 * 1.8 * 277/283\n= 1.01e5 * 1.8 * 0.97881 = 1.7795e5\np1 - p0 = ρgh\nh = (1.7795e5 - 1.01e5)/(1000*9.8) = 76950/9800 = 7.852 m\n\n{"final_numeric": 7.85, "final_formula": "h = \\\\frac{p_0}{\\\\rho g}\\\\left(\\\\frac{V_2 T_1}{V_1 T_2} - 1\\\\right)", "final_units": "m"}', 'refusal': None, 'reasoning': None}}], 'usage': {'prompt_tokens': 900, 'completion_tokens': 228, 'total_tokens': 1128, 'cost': 0.0102, 'is_byok': False, 'prompt_tokens_details': {'cached_tokens': 0, 'cache_write_tokens': 0, 'audio_tokens': 0, 'video_tokens': 0}, 'cost_details': {'upstream_inference_cost': 0.0102, 'upstream_inference_prompt_cost': 0.0045, 'upstream_inference_completions_cost': 0.0057}, 'completion_tokens_details': {'reasoning_tokens': 0, 'image_tokens': 0, 'audio_tokens': 0}}} | L9: 900 | M9: 228 | N9: 1128 | O9: 0 | P9: =VLOOKUP(C9,problems!$A$2:$B$26,2) -> thermodynamics | Q9: =IFERROR(__xludf.DUMMYFUNCTION("INDEX(FILTER('stats2-openrouter_activity_2026'!C:C,L9='stats2-openrouter_activity_2026'!H:H,M9='stats2-openrouter_activity_2026'!I:I, B9='stats2-openrouter_activity_2026'!M:M),1)"),0.0102) -> 0.0102 | R9: =IFS( F9=VLOOKUP($C9,problems!$A$2:$G$26,6),1, True,0 ) -> 0 | S9: =IFS( G9=VLOOKUP($C9,problems!$A$2:$G$26,4),1, G9=VLOOKUP($C9,problems!$A$2:$G$26,5),1, True,0 ) -> 0 | T9: =IFS( H9=VLOOKUP($C9,problems!$A$2:$G$26,7),1, True,0 ) -> 1
A10: 2026-06-03-17-19-27 | B10: anthropic/claude-opus-4.7 | C10: 9 | D10: Given: T = 30∘C — air temperature. T_d = 15∘C — dew-point temperature, because condensation first appears when the can reaches 15∘C. Find: \phi\ — relative humidity of the air, in percent. | E10: TRUE | F10: 40.1 | G10: \phi = \frac{p_s(T_d)}{p_s(T)} = \frac{1.705\,\text{kPa}}{4.246\,\text{kPa}} \approx 0.40 | H10: % | J10: {"final_numeric":40.1,"final_formula":"\\phi = \\frac{p_s(T_d)}{p_s(T)} = \\frac{1.705\\,\\text{kPa}}{4.246\\,\\text{kPa}} \\approx 0.40","final_units":"%"} | K10: {'id': 'gen-1780492765-WSex6mz8YTf7mChXmTrJ', 'object': 'chat.completion', 'created': 1780492765, 'model': 'anthropic/claude-4.7-opus-20260416', 'provider': 'Anthropic', 'system_fingerprint': None, 'service_tier': 'default', 'choices': [{'index': 0, 'logprobs': None, 'finish_reason': 'stop', 'native_finish_reason': 'end_turn', 'message': {'role': 'assistant', 'content': '{"final_numeric":40.1,"final_formula":"\\\\phi = \\\\frac{p_s(T_d)}{p_s(T)} = \\\\frac{1.705\\\\,\\\\text{kPa}}{4.246\\\\,\\\\text{kPa}} \\\\approx 0.40","final_units":"%"}', 'refusal': None, 'reasoning': None}}], 'usage': {'prompt_tokens': 793, 'completion_tokens': 104, 'total_tokens': 897, 'cost': 0.006565, 'is_byok': False, 'prompt_tokens_details': {'cached_tokens': 0, 'cache_write_tokens': 0, 'audio_tokens': 0, 'video_tokens': 0}, 'cost_details': {'upstream_inference_cost': 0.006565, 'upstream_inference_prompt_cost': 0.003965, 'upstream_inference_completions_cost': 0.0026}, 'completion_tokens_details': {'reasoning_tokens': 0, 'image_tokens': 0, 'audio_tokens': 0}}} | L10: 793 | M10: 104 | N10: 897 | O10: 0 | P10: =VLOOKUP(C10,problems!$A$2:$B$26,2) -> thermodynamics | Q10: =IFERROR(__xludf.DUMMYFUNCTION("INDEX(FILTER('stats2-openrouter_activity_2026'!C:C,L10='stats2-openrouter_activity_2026'!H:H,M10='stats2-openrouter_activity_2026'!I:I, B10='stats2-openrouter_activity_2026'!M:M),1)"),0.006565) -> 0.006565 | R10: =IFS( F10=VLOOKUP($C10,problems!$A$2:$G$26,6),1, True,0 ) -> 0 | S10: =IFS( G10=VLOOKUP($C10,problems!$A$2:$G$26,4),1, G10=VLOOKUP($C10,problems!$A$2:$G$26,5),1, True,0 ) -> 0 | T10: =IFS( H10=VLOOKUP($C10,problems!$A$2:$G$26,7),1, True,0 ) -> 1
A11: 2026-06-03-17-21-21 | B11: anthropic/claude-opus-4.7 | C11: 10 | D11: Дано: V_1 = 10л — начальный объем газа. p_1 = 2 * 10^5 Па — начальное давление газа. V_2 = 28 л — конечный объем газа. Процесс - изотермический Найти: A — работа, совершенная газом при изотермическом расширении, в кДж. | E11: TRUE | F11: 2.06 | G11: A = p_1 V_1 \ln\frac{V_2}{V_1} | H11: kJ | J11: {"final_numeric":2.06,"final_formula":"A = p_1 V_1 \\ln\\frac{V_2}{V_1}","final_units":"kJ"} | K11: {'id': 'gen-1780492878-SjHM6dJzshN6FvKMuu3T', 'object': 'chat.completion', 'created': 1780492878, 'model': 'anthropic/claude-4.7-opus-20260416', 'provider': 'Anthropic', 'system_fingerprint': None, 'service_tier': 'default', 'choices': [{'index': 0, 'logprobs': None, 'finish_reason': 'stop', 'native_finish_reason': 'end_turn', 'message': {'role': 'assistant', 'content': '{"final_numeric":2.06,"final_formula":"A = p_1 V_1 \\\\ln\\\\frac{V_2}{V_1}","final_units":"kJ"}', 'refusal': None, 'reasoning': None}}], 'usage': {'prompt_tokens': 823, 'completion_tokens': 62, 'total_tokens': 885, 'cost': 0.005665, 'is_byok': False, 'prompt_tokens_details': {'cached_tokens': 0, 'cache_write_tokens': 0, 'audio_tokens': 0, 'video_tokens': 0}, 'cost_details': {'upstream_inference_cost': 0.005665, 'upstream_inference_prompt_cost': 0.004115, 'upstream_inference_completions_cost': 0.00155}, 'completion_tokens_details': {'reasoning_tokens': 0, 'image_tokens': 0, 'audio_tokens': 0}}} | L11: 823 | M11: 62 | N11: 885 | O11: 0 | P11: =VLOOKUP(C11,problems!$A$2:$B$26,2) -> thermodynamics | Q11: =IFERROR(__xludf.DUMMYFUNCTION("INDEX(FILTER('stats2-openrouter_activity_2026'!C:C,L11='stats2-openrouter_activity_2026'!H:H,M11='stats2-openrouter_activity_2026'!I:I, B11='stats2-openrouter_activity_2026'!M:M),1)"),0.005665) -> 0.005665 | R11: =IFS( F11=VLOOKUP($C11,problems!$A$2:$G$26,6),1, True,0 ) -> 1 | S11: =IFS( G11=VLOOKUP($C11,problems!$A$2:$G$26,4),1, G11=VLOOKUP($C11,problems!$A$2:$G$26,5),1, True,0 ) -> 0 | T11: =IFS( H11=VLOOKUP($C11,problems!$A$2:$G$26,7),1, True,0 ) -> 1
A12: 2026-06-03-17-24-27 | B12: anthropic/claude-opus-4.7 | C12: 11 | D12: Given: h_0 = 3.5 mm — height of the object, the printed letters. d_c = 30 cm — distance from the book to the eye. d_i = 2 cm — distance from the eye lens to the retina. Find: h_i — the height of the image of the print on the retina, in millimeters. | E12: TRUE | F12: 0.233 | G12: h_i = h_0 \cdot \frac{d_i}{d_c} | H12: mm | J12: {"final_numeric":0.233,"final_formula":"h_i = h_0 \\cdot \\frac{d_i}{d_c}","final_units":"mm"} | K12: {'id': 'gen-1780493065-Br9cqqmhRgnQnfpwnvQB', 'object': 'chat.completion', 'created': 1780493065, 'model': 'anthropic/claude-4.7-opus-20260416', 'provider': 'Anthropic', 'system_fingerprint': None, 'service_tier': 'default', 'choices': [{'index': 0, 'logprobs': None, 'finish_reason': 'stop', 'native_finish_reason': 'end_turn', 'message': {'role': 'assistant', 'content': '{"final_numeric":0.233,"final_formula":"h_i = h_0 \\\\cdot \\\\frac{d_i}{d_c}","final_units":"mm"}', 'refusal': None, 'reasoning': None}}], 'usage': {'prompt_tokens': 815, 'completion_tokens': 60, 'total_tokens': 875, 'cost': 0.005575, 'is_byok': False, 'prompt_tokens_details': {'cached_tokens': 0, 'cache_write_tokens': 0, 'audio_tokens': 0, 'video_tokens': 0}, 'cost_details': {'upstream_inference_cost': 0.005575, 'upstream_inference_prompt_cost': 0.004075, 'upstream_inference_completions_cost': 0.0015}, 'completion_tokens_details': {'reasoning_tokens': 0, 'image_tokens': 0, 'audio_tokens': 0}}} | L12: 815 | M12: 60 | N12: 875 | O12: 0 | P12: =VLOOKUP(C12,problems!$A$2:$B$26,2) -> optics | Q12: =IFERROR(__xludf.DUMMYFUNCTION("INDEX(FILTER('stats2-openrouter_activity_2026'!C:C,L12='stats2-openrouter_activity_2026'!H:H,M12='stats2-openrouter_activity_2026'!I:I, B12='stats2-openrouter_activity_2026'!M:M),1)"),0.005575) -> 0.005575 | R12: =IFS( F12=VLOOKUP($C12,problems!$A$2:$G$26,6),1, True,0 ) -> 0 | S12: =IFS( G12=VLOOKUP($C12,problems!$A$2:$G$26,4),1, G12=VLOOKUP($C12,problems!$A$2:$G$26,5),1, True,0 ) -> 0 | T12: =IFS( H12=VLOOKUP($C12,problems!$A$2:$G$26,7),1, True,0 ) -> 1
A13: 2026-06-03-17-26-23 | B13: anthropic/claude-opus-4.7 | C13: 12 | D13: Given: f_{obj} = 100 cm — focal length of the objective lens. f_{eye} = 2.50 cm — focal length of the eyepiece. Find: M — angular magnification of the telescope. | E13: TRUE | F13: -40 | G13: M=-\frac{f_{obj}}{f_{eye}} | H13: 1 | J13: {"final_numeric":-40,"final_formula":"M=-\\frac{f_{obj}}{f_{eye}}","final_units":"1"} | K13: {'id': 'gen-1780493182-YiuPMVUJWvzwww3ZQS7x', 'object': 'chat.completion', 'created': 1780493182, 'model': 'anthropic/claude-4.7-opus-20260416', 'provider': 'Anthropic', 'system_fingerprint': None, 'service_tier': 'default', 'choices': [{'index': 0, 'logprobs': None, 'finish_reason': 'stop', 'native_finish_reason': 'end_turn', 'message': {'role': 'assistant', 'content': '{"final_numeric":-40,"final_formula":"M=-\\\\frac{f_{obj}}{f_{eye}}","final_units":"1"}', 'refusal': None, 'reasoning': None}}], 'usage': {'prompt_tokens': 786, 'completion_tokens': 54, 'total_tokens': 840, 'cost': 0.00528, 'is_byok': False, 'prompt_tokens_details': {'cached_tokens': 0, 'cache_write_tokens': 0, 'audio_tokens': 0, 'video_tokens': 0}, 'cost_details': {'upstream_inference_cost': 0.00528, 'upstream_inference_prompt_cost': 0.00393, 'upstream_inference_completions_cost': 0.00135}, 'completion_tokens_details': {'reasoning_tokens': 0, 'image_tokens': 0, 'audio_tokens': 0}}} | L13: 786 | M13: 54 | N13: 840 | O13: 0 | P13: =VLOOKUP(C13,problems!$A$2:$B$26,2) -> optics | Q13: =IFERROR(__xludf.DUMMYFUNCTION("INDEX(FILTER('stats2-openrouter_activity_2026'!C:C,L13='stats2-openrouter_activity_2026'!H:H,M13='stats2-openrouter_activity_2026'!I:I, B13='stats2-openrouter_activity_2026'!M:M),1)"),0.00528) -> 0.00528 | R13: =IFS( F13=VLOOKUP($C13,problems!$A$2:$G$26,6),1, True,0 ) -> 1 | S13: =IFS( G13=VLOOKUP($C13,problems!$A$2:$G$26,4),1, G13=VLOOKUP($C13,problems!$A$2:$G$26,5),1, True,0 ) -> 0 | T13: =IFS( H13=VLOOKUP($C13,problems!$A$2:$G$26,7),1, True,0 ) -> 1
A14: 2026-06-03-17-27-19 | B14: anthropic/claude-opus-4.7 | C14: 13 | D14: Дано: Луч последовательно отражается от двух плоских зеркал. Луч, падающий на первое зеркало, параллелен плоскости второго зеркала. Дважды отражённый луч параллелен плоскости первого зеркала. Найти: phi — угол между зеркалами, в градусах. | E14: TRUE | F14: 60 | G14: \varphi = \arccos\frac{1}{2} = 60^\circ | H14: deg | J14: Angle between mirrors φ. Incident ray parallel to mirror 2, so angle with mirror 1 is φ, meaning angle of incidence (from normal) is 90-φ. After reflection, ray makes angle φ with mirror 1 on other side. Let me set mirror 1 along direction making angle 0, mirror 2 at angle φ. Incident ray parallel to mirror 2. After two reflections, total deviation... Final ray parallel to mirror 1. Using angles: incident ray direction parallel to mirror 2. After reflecting off mirror 1, then mirror 2, ray is parallel to mirror 1. The angle between incident and final ray after two reflections from mirrors at angle φ is 2φ (or 180-2φ). Let me think more carefully. Incident ray parallel to mirror 2 → angle with mirror 1 = φ. Reflects, makes angle φ with mirror 1 on other side. This ray hits mirror 2; angle with mirror 2 = ? The reflected ray from mirror 1 and mirror 2 — angle between them = φ - ... Set mirror 1 along x-axis, mirror 2 at angle φ above. Incident ray parallel to mirror 2, direction (-cos φ, -sin φ) coming down to mirror 1. Reflects off mirror 1 (flip y): direction (-cos φ, sin φ). This hits mirror 2. Mirror 2 normal: (-sin φ, cos φ). Reflect: r = d - 2(d·n)n. d·n = (-cos φ)(-sin φ) + (sin φ)(cos φ) = 2 sin φ cos φ = sin 2φ. r = (-cos φ + 2 sin 2φ sin φ, sin φ - 2 sin 2φ cos φ) = (-cos φ + 4 sin²φ cos φ, sin φ - 4 sin φ cos²φ) = (cos φ(4sin²φ - 1), sin φ(1 - 4cos²φ)) For this to be parallel to mirror 1 (x-axis), y-component = 0: sin φ(1 - 4cos²φ) = 0 cos²φ = 1/4, cos φ = 1/2, φ = 60°. {"final_numeric":60,"final_formula":"\\varphi = \\arccos\\frac{1}{2} = 60^\\circ","final_units":"deg"} | K14: {'id': 'gen-1780493228-k12menPo8MPxQae6Y2BJ', 'object': 'chat.completion', 'created': 1780493228, 'model': 'anthropic/claude-4.7-opus-20260416', 'provider': 'Anthropic', 'system_fingerprint': None, 'service_tier': 'default', 'choices': [{'index': 0, 'logprobs': None, 'finish_reason': 'stop', 'native_finish_reason': 'end_turn', 'message': {'role': 'assistant', 'content': 'Angle between mirrors φ. Incident ray parallel to mirror 2, so angle with mirror 1 is φ, meaning angle of incidence (from normal) is 90-φ. After reflection, ray makes angle φ with mirror 1 on other side.\n\nLet me set mirror 1 along direction making angle 0, mirror 2 at angle φ. Incident ray parallel to mirror 2.\n\nAfter two reflections, total deviation... Final ray parallel to mirror 1.\n\nUsing angles: incident ray direction parallel to mirror 2. After reflecting off mirror 1, then mirror 2, ray is parallel to mirror 1.\n\nThe angle between incident and final ray after two reflections from mirrors at angle φ is 2φ (or 180-2φ). \n\nLet me think more carefully. Incident ray parallel to mirror 2 → angle with mirror 1 = φ. Reflects, makes angle φ with mirror 1 on other side. This ray hits mirror 2; angle with mirror 2 = ? The reflected ray from mirror 1 and mirror 2 — angle between them = φ - ... \n\nSet mirror 1 along x-axis, mirror 2 at angle φ above. Incident ray parallel to mirror 2, direction (-cos φ, -sin φ) coming down to mirror 1. Reflects off mirror 1 (flip y): direction (-cos φ, sin φ). This hits mirror 2. Mirror 2 normal: (-sin φ, cos φ). Reflect: r = d - 2(d·n)n.\nd·n = (-cos φ)(-sin φ) + (sin φ)(cos φ) = 2 sin φ cos φ = sin 2φ.\nr = (-cos φ + 2 sin 2φ sin φ, sin φ - 2 sin 2φ cos φ)\n= (-cos φ + 4 sin²φ cos φ, sin φ - 4 sin φ cos²φ)\n= (cos φ(4sin²φ - 1), sin φ(1 - 4cos²φ))\n\nFor this to be parallel to mirror 1 (x-axis), y-component = 0:\nsin φ(1 - 4cos²φ) = 0\ncos²φ = 1/4, cos φ = 1/2, φ = 60°.\n\n{"final_numeric":60,"final_formula":"\\\\varphi = \\\\arccos\\\\frac{1}{2} = 60^\\\\circ","final_units":"deg"}', 'refusal': None, 'reasoning': None}}], 'usage': {'prompt_tokens': 820, 'completion_tokens': 823, 'total_tokens': 1643, 'cost': 0.024675, 'is_byok': False, 'prompt_tokens_details': {'cached_tokens': 0, 'cache_write_tokens': 0, 'audio_tokens': 0, 'video_tokens': 0}, 'cost_details': {'upstream_inference_cost': 0.024675, 'upstream_inference_prompt_cost': 0.0041, 'upstream_inference_completions_cost': 0.020575}, 'completion_tokens_details': {'reasoning_tokens': 0, 'image_tokens': 0, 'audio_tokens': 0}}} | L14: 820 | M14: 823 | N14: 1643 | O14: 0 | P14: =VLOOKUP(C14,problems!$A$2:$B$26,2) -> optics | Q14: =IFERROR(__xludf.DUMMYFUNCTION("INDEX(FILTER('stats2-openrouter_activity_2026'!C:C,L14='stats2-openrouter_activity_2026'!H:H,M14='stats2-openrouter_activity_2026'!I:I, B14='stats2-openrouter_activity_2026'!M:M),1)"),0.024675) -> 0.024675 | R14: =IFS( F14=VLOOKUP($C14,problems!$A$2:$G$26,6),1, True,0 ) -> 1 | S14: =IFS( G14=VLOOKUP($C14,problems!$A$2:$G$26,4),1, G14=VLOOKUP($C14,problems!$A$2:$G$26,5),1, True,0 ) -> 0 | T14: =IFS( H14=VLOOKUP($C14,problems!$A$2:$G$26,7),1, True,0 ) -> 0
A15: 2026-06-03-17-29-59 | B15: anthropic/claude-opus-4.7 | C15: 14 | D15: Дано: Сосуд заполнен водой, на дне лежит плоское зеркало. d = 25 см — расстояние, на котором человек видит изображение своего лица в зеркале. h = 5 см — расстояние от лица до поверхности воды. n = \frac{4}{3} — показатель преломления воды. Найти: l — глубину сосуда, в сантиметрах. | E15: TRUE | F15: 13.33 | G15: l = \frac{n(d-h)}{2} | H15: cm | J15: Distance person sees image = d = 25 cm = h + apparent depth of image. Image is at 2l below surface (mirror image), apparent depth = 2l/n. So d = h + 2l/n → 2l/n = 20 → l = 20·(4/3)/2 = 40/3 ≈ 13.33 cm. {"final_numeric":13.33,"final_formula":"l = \\frac{n(d-h)}{2}","final_units":"cm"} | K15: {'id': 'gen-1780493395-t5BI4PCNmk7MWqI2J0Nt', 'object': 'chat.completion', 'created': 1780493395, 'model': 'anthropic/claude-4.7-opus-20260416', 'provider': 'Anthropic', 'system_fingerprint': None, 'service_tier': 'default', 'choices': [{'index': 0, 'logprobs': None, 'finish_reason': 'stop', 'native_finish_reason': 'end_turn', 'message': {'role': 'assistant', 'content': 'Distance person sees image = d = 25 cm = h + apparent depth of image.\nImage is at 2l below surface (mirror image), apparent depth = 2l/n.\nSo d = h + 2l/n → 2l/n = 20 → l = 20·(4/3)/2 = 40/3 ≈ 13.33 cm.\n\n{"final_numeric":13.33,"final_formula":"l = \\\\frac{n(d-h)}{2}","final_units":"cm"}', 'refusal': None, 'reasoning': None}}], 'usage': {'prompt_tokens': 847, 'completion_tokens': 159, 'total_tokens': 1006, 'cost': 0.00821, 'is_byok': False, 'prompt_tokens_details': {'cached_tokens': 0, 'cache_write_tokens': 0, 'audio_tokens': 0, 'video_tokens': 0}, 'cost_details': {'upstream_inference_cost': 0.00821, 'upstream_inference_prompt_cost': 0.004235, 'upstream_inference_completions_cost': 0.003975}, 'completion_tokens_details': {'reasoning_tokens': 0, 'image_tokens': 0, 'audio_tokens': 0}}} | L15: 847 | M15: 159 | N15: 1006 | O15: 0 | P15: =VLOOKUP(C15,problems!$A$2:$B$26,2) -> optics | Q15: =IFERROR(__xludf.DUMMYFUNCTION("INDEX(FILTER('stats2-openrouter_activity_2026'!C:C,L15='stats2-openrouter_activity_2026'!H:H,M15='stats2-openrouter_activity_2026'!I:I, B15='stats2-openrouter_activity_2026'!M:M),1)"),0.00821) -> 0.00821 | R15: =IFS( F15=VLOOKUP($C15,problems!$A$2:$G$26,6),1, True,0 ) -> 0 | S15: =IFS( G15=VLOOKUP($C15,problems!$A$2:$G$26,4),1, G15=VLOOKUP($C15,problems!$A$2:$G$26,5),1, True,0 ) -> 0 | T15: =IFS( H15=VLOOKUP($C15,problems!$A$2:$G$26,7),1, True,0 ) -> 1
A16: 2026-06-03-17-32-45 | B16: anthropic/claude-opus-4.7 | C16: 15 | D16: Given: A beam of light falls on a single slit. a = 1.00𝜇m — width of the single slit. theta = 36.9∘ — angle at which the first minimum occurs. m = 1 — order of the first minimum. Find: lambda — wavelength of the light, in nanometers. | E16: TRUE | F16: 600 | G16: \lambda = \frac{a \sin\theta}{m} | H16: nm | J16: {"final_numeric":600,"final_formula":"\\lambda = \\frac{a \\sin\\theta}{m}","final_units":"nm"} | K16: {'id': 'gen-1780493563-YB4ZTzmX81CkWOSWALqi', 'object': 'chat.completion', 'created': 1780493563, 'model': 'anthropic/claude-4.7-opus-20260416', 'provider': 'Anthropic', 'system_fingerprint': None, 'service_tier': 'default', 'choices': [{'index': 0, 'logprobs': None, 'finish_reason': 'stop', 'native_finish_reason': 'end_turn', 'message': {'role': 'assistant', 'content': '{"final_numeric":600,"final_formula":"\\\\lambda = \\\\frac{a \\\\sin\\\\theta}{m}","final_units":"nm"}', 'refusal': None, 'reasoning': None}}], 'usage': {'prompt_tokens': 814, 'completion_tokens': 55, 'total_tokens': 869, 'cost': 0.005445, 'is_byok': False, 'prompt_tokens_details': {'cached_tokens': 0, 'cache_write_tokens': 0, 'audio_tokens': 0, 'video_tokens': 0}, 'cost_details': {'upstream_inference_cost': 0.005445, 'upstream_inference_prompt_cost': 0.00407, 'upstream_inference_completions_cost': 0.001375}, 'completion_tokens_details': {'reasoning_tokens': 0, 'image_tokens': 0, 'audio_tokens': 0}}} | L16: 814 | M16: 55 | N16: 869 | O16: 0 | P16: =VLOOKUP(C16,problems!$A$2:$B$26,2) -> optics | Q16: =IFERROR(__xludf.DUMMYFUNCTION("INDEX(FILTER('stats2-openrouter_activity_2026'!C:C,L16='stats2-openrouter_activity_2026'!H:H,M16='stats2-openrouter_activity_2026'!I:I, B16='stats2-openrouter_activity_2026'!M:M),1)"),0.005445) -> 0.005445 | R16: =IFS( F16=VLOOKUP($C16,problems!$A$2:$G$26,6),1, True,0 ) -> 1 | S16: =IFS( G16=VLOOKUP($C16,problems!$A$2:$G$26,4),1, G16=VLOOKUP($C16,problems!$A$2:$G$26,5),1, True,0 ) -> 0 | T16: =IFS( H16=VLOOKUP($C16,problems!$A$2:$G$26,7),1, True,0 ) -> 1
A17: 2026-06-03-17-36-12 | B17: anthropic/claude-opus-4.7 | C17: 16 | D17: Дано: l = 1 м — длина тонкого непроводящего горизонтального стержня На концах стержня закреплены две маленькие бусинки. Третья бусинка надета на стержень и может двигаться по нему без трения. Всем бусинкам сообщены одинаковые заряды q = 10^-6 Кл m = 5 г — масса подвижной бусинки Подвижная бусинка совершает малые колебания около середины стержня. Найти: T — период малых колебаний подвижной бусинки, в секундах. | E17: TRUE | F17: 0.828 | G17: T = 2\pi\sqrt{\dfrac{m l^3}{32 k q^2}} = \pi\sqrt{\dfrac{m l^3}{8 k q^2}} | H17: s | J17: Let me set up: bead at position x from center, distance to ends l/2-x and l/2+x. Force = kq²[1/(l/2-x)² - 1/(l/2+x)²] For small x: expand. 1/(l/2-x)² ≈ (4/l²)(1+4x/l), 1/(l/2+x)² ≈ (4/l²)(1-4x/l) Difference ≈ (4/l²)(8x/l) = 32x/l³ F = kq² · 32x/l³, this is restoring? Force pushes away from nearer charge, so when x>0, force is in +x direction (away from center toward... wait). Charge at +l/2 pushes bead (at x) toward -x: force = -kq²/(l/2-x)² Charge at -l/2 pushes toward +x: force = +kq²/(l/2+x)² Net F = kq²/(l/2+x)² - kq²/(l/2-x)² ≈ -kq²·32x/l³ So restoring. ω² = 32kq²/(ml³) k = 8.99e9, q² = 1e-12, m = 5e-3, l³ = 1 ω² = 32 · 8.99e9 · 1e-12 / 5e-3 = 32 · 8.99e-3/5e-3 = 32·1.798 = 57.536 ω = 7.585 T = 2π/ω = 0.828 s {"final_numeric": 0.828, "final_formula": "T = 2\\pi\\sqrt{\\dfrac{m l^3}{32 k q^2}} = \\pi\\sqrt{\\dfrac{m l^3}{8 k q^2}}", "final_units": "s"} | K17: {'id': 'gen-1780493763-KO6i76ziFgkgvNZzgeQ7', 'object': 'chat.completion', 'created': 1780493763, 'model': 'anthropic/claude-4.7-opus-20260416', 'provider': 'Anthropic', 'system_fingerprint': None, 'service_tier': 'default', 'choices': [{'index': 0, 'logprobs': None, 'finish_reason': 'stop', 'native_finish_reason': 'end_turn', 'message': {'role': 'assistant', 'content': 'Let me set up: bead at position x from center, distance to ends l/2-x and l/2+x.\n\nForce = kq²[1/(l/2-x)² - 1/(l/2+x)²]\n\nFor small x: expand. 1/(l/2-x)² ≈ (4/l²)(1+4x/l), 1/(l/2+x)² ≈ (4/l²)(1-4x/l)\nDifference ≈ (4/l²)(8x/l) = 32x/l³\n\nF = kq² · 32x/l³, this is restoring? Force pushes away from nearer charge, so when x>0, force is in +x direction (away from center toward... wait).\n\nCharge at +l/2 pushes bead (at x) toward -x: force = -kq²/(l/2-x)²\nCharge at -l/2 pushes toward +x: force = +kq²/(l/2+x)²\n\nNet F = kq²/(l/2+x)² - kq²/(l/2-x)² ≈ -kq²·32x/l³\n\nSo restoring. ω² = 32kq²/(ml³)\n\nk = 8.99e9, q² = 1e-12, m = 5e-3, l³ = 1\nω² = 32 · 8.99e9 · 1e-12 / 5e-3 = 32 · 8.99e-3/5e-3 = 32·1.798 = 57.536\nω = 7.585\nT = 2π/ω = 0.828 s\n\n{"final_numeric": 0.828, "final_formula": "T = 2\\\\pi\\\\sqrt{\\\\dfrac{m l^3}{32 k q^2}} = \\\\pi\\\\sqrt{\\\\dfrac{m l^3}{8 k q^2}}", "final_units": "s"}', 'refusal': None, 'reasoning': None}}], 'usage': {'prompt_tokens': 897, 'completion_tokens': 570, 'total_tokens': 1467, 'cost': 0.018735, 'is_byok': False, 'prompt_tokens_details': {'cached_tokens': 0, 'cache_write_tokens': 0, 'audio_tokens': 0, 'video_tokens': 0}, 'cost_details': {'upstream_inference_cost': 0.018735, 'upstream_inference_prompt_cost': 0.004485, 'upstream_inference_completions_cost': 0.01425}, 'completion_tokens_details': {'reasoning_tokens': 0, 'image_tokens': 0, 'audio_tokens': 0}}} | L17: 897 | M17: 570 | N17: 1467 | O17: 0 | P17: =VLOOKUP(C17,problems!$A$2:$B$26,2) -> electrostatics | Q17: =IFERROR(__xludf.DUMMYFUNCTION("INDEX(FILTER('stats2-openrouter_activity_2026'!C:C,L17='stats2-openrouter_activity_2026'!H:H,M17='stats2-openrouter_activity_2026'!I:I, B17='stats2-openrouter_activity_2026'!M:M),1)"),0.018735) -> 0.018735 | R17: =IFS( F17=VLOOKUP($C17,problems!$A$2:$G$26,6),1, True,0 ) -> 0 | S17: =IFS( G17=VLOOKUP($C17,problems!$A$2:$G$26,4),1, G17=VLOOKUP($C17,problems!$A$2:$G$26,5),1, True,0 ) -> 0 | T17: =IFS( H17=VLOOKUP($C17,problems!$A$2:$G$26,7),1, True,0 ) -> 1
A18: 2026-06-03-17-40-40 | B18: anthropic/claude-opus-4.7 | C18: 17 | D18: E = 10^6 В/м — максимальная напряжённость электрического поля, при которой воздух ещё остаётся изолятором. q = 1 Кл — заряд металлического шара. Найти: R — радиус металлического шара, при котором на нём может удержаться заряд, в метрах. | E18: TRUE | F18: 94.87 | G18: R = \sqrt{\dfrac{kq}{E}} | H18: m | J18: R = sqrt(kq/E) = sqrt(9e9 * 1 / 1e6) = sqrt(9000) ≈ 94.87 m { "final_numeric": 94.87, "final_formula": "R = \\sqrt{\\dfrac{kq}{E}}", "final_units": "m" } | K18: {'id': 'gen-1780494037-whFuhtsC1ARAFO2VXkFs', 'object': 'chat.completion', 'created': 1780494037, 'model': 'anthropic/claude-4.7-opus-20260416', 'provider': 'Anthropic', 'system_fingerprint': None, 'service_tier': 'default', 'choices': [{'index': 0, 'logprobs': None, 'finish_reason': 'stop', 'native_finish_reason': 'end_turn', 'message': {'role': 'assistant', 'content': 'R = sqrt(kq/E) = sqrt(9e9 * 1 / 1e6) = sqrt(9000) ≈ 94.87 m\n\n{\n "final_numeric": 94.87,\n "final_formula": "R = \\\\sqrt{\\\\dfrac{kq}{E}}",\n "final_units": "m"\n}', 'refusal': None, 'reasoning': None}}], 'usage': {'prompt_tokens': 814, 'completion_tokens': 116, 'total_tokens': 930, 'cost': 0.00697, 'is_byok': False, 'prompt_tokens_details': {'cached_tokens': 0, 'cache_write_tokens': 0, 'audio_tokens': 0, 'video_tokens': 0}, 'cost_details': {'upstream_inference_cost': 0.00697, 'upstream_inference_prompt_cost': 0.00407, 'upstream_inference_completions_cost': 0.0029}, 'completion_tokens_details': {'reasoning_tokens': 0, 'image_tokens': 0, 'audio_tokens': 0}}} | L18: 814 | M18: 116 | N18: 930 | O18: 0 | P18: =VLOOKUP(C18,problems!$A$2:$B$26,2) -> electrostatics | Q18: =IFERROR(__xludf.DUMMYFUNCTION("INDEX(FILTER('stats2-openrouter_activity_2026'!C:C,L18='stats2-openrouter_activity_2026'!H:H,M18='stats2-openrouter_activity_2026'!I:I, B18='stats2-openrouter_activity_2026'!M:M),1)"),0.00697) -> 0.00697 | R18: =IFS( F18=VLOOKUP($C18,problems!$A$2:$G$26,6),1, True,0 ) -> 0 | S18: =IFS( G18=VLOOKUP($C18,problems!$A$2:$G$26,4),1, G18=VLOOKUP($C18,problems!$A$2:$G$26,5),1, True,0 ) -> 0 | T18: =IFS( H18=VLOOKUP($C18,problems!$A$2:$G$26,7),1, True,0 ) -> 1
A19: 2026-06-03-17-43-08 | B19: anthropic/claude-opus-4.7 | C19: 18 | D19: Дано: E = 100 В/м — напряжённость однородного электрического поля. v_0 = 10^6 м/с — начальная скорость электрона. v = 0 — конечная скорость электрона Электрон движется вдоль силовой линии поля, но сила, действующая на электрон, направлена противоположно полю, поэтому электрон тормозит. Найти: s — расстояние до полной остановки электрона, в сантиметрах. | E19: TRUE | F19: 2.85 | G19: s = \frac{m_e v_0^2}{2eE} | H19: cm | J19: s = mv²/(2eE) = (9.11e-31 × 1e12)/(2 × 1.6e-19 × 100) = 9.11e-19/3.2e-17 = 0.02847 m ≈ 2.85 cm {"final_numeric":2.85,"final_formula":"s = \\frac{m_e v_0^2}{2eE}","final_units":"cm"} | K19: {'id': 'gen-1780494185-pTMyFWHXV0Z4cQudlNTA', 'object': 'chat.completion', 'created': 1780494185, 'model': 'anthropic/claude-4.7-opus-20260416', 'provider': 'Anthropic', 'system_fingerprint': None, 'service_tier': 'default', 'choices': [{'index': 0, 'logprobs': None, 'finish_reason': 'stop', 'native_finish_reason': 'end_turn', 'message': {'role': 'assistant', 'content': 's = mv²/(2eE) = (9.11e-31 × 1e12)/(2 × 1.6e-19 × 100) = 9.11e-19/3.2e-17 = 0.02847 m ≈ 2.85 cm\n\n{"final_numeric":2.85,"final_formula":"s = \\\\frac{m_e v_0^2}{2eE}","final_units":"cm"}', 'refusal': None, 'reasoning': None}}], 'usage': {'prompt_tokens': 866, 'completion_tokens': 133, 'total_tokens': 999, 'cost': 0.007655, 'is_byok': False, 'prompt_tokens_details': {'cached_tokens': 0, 'cache_write_tokens': 0, 'audio_tokens': 0, 'video_tokens': 0}, 'cost_details': {'upstream_inference_cost': 0.007655, 'upstream_inference_prompt_cost': 0.00433, 'upstream_inference_completions_cost': 0.003325}, 'completion_tokens_details': {'reasoning_tokens': 0, 'image_tokens': 0, 'audio_tokens': 0}}} | L19: 866 | M19: 133 | N19: 999 | O19: 0 | P19: =VLOOKUP(C19,problems!$A$2:$B$26,2) -> electrostatics | Q19: =IFERROR(__xludf.DUMMYFUNCTION("INDEX(FILTER('stats2-openrouter_activity_2026'!C:C,L19='stats2-openrouter_activity_2026'!H:H,M19='stats2-openrouter_activity_2026'!I:I, B19='stats2-openrouter_activity_2026'!M:M),1)"),0.007655) -> 0.007655 | R19: =IFS( F19=VLOOKUP($C19,problems!$A$2:$G$26,6),1, True,0 ) -> 0 | S19: =IFS( G19=VLOOKUP($C19,problems!$A$2:$G$26,4),1, G19=VLOOKUP($C19,problems!$A$2:$G$26,5),1, True,0 ) -> 0 | T19: =IFS( H19=VLOOKUP($C19,problems!$A$2:$G$26,7),1, True,0 ) -> 1
A20: 2026-06-03-17-45-46 | B20: anthropic/claude-opus-4.7 | C20: 19 | D20: Дано: Два одинаковых воздушных конденсатора соединены последовательно. Они подключены к батарее с постоянной ЭДС, поэтому U = const Один из конденсаторов заполняют диэлектриком: epsilon — диэлектрическая проницаемость вещества. До внесения диэлектрика оба конденсатора были одинаковыми: C_1 = C_2 = C После внесения диэлектрика ёмкость одного конденсатора становится: C'_{1} = epsilon*C Найти: E/E_0 — во сколько раз изменится напряжённость электрического поля в конденсаторе, заполненном диэлектриком. | E20: TRUE | G20: \dfrac{E}{E_0} = \dfrac{2}{\varepsilon+1} | H20: 1 | J20: Initially: C_series = C/2, U on each = U/2, E_0 = U/(2d). After: C'_1 = εC, C_2 = C. Series total. Voltage on dielectric cap: U_1 = U·C_2/(C_1'+C_2) = U/(ε+1). Field in dielectric: E = U_1/(ε·d)... wait, field in dielectric E = U_1/d (the geometric distance), but reduced by ε from free charge. Actually E = U_1/d where d is plate separation. E/E_0 = [U/((ε+1)d)] / [U/(2d)] = 2/(ε+1). { "final_numeric": null, "final_formula": "\\dfrac{E}{E_0} = \\dfrac{2}{\\varepsilon+1}", "final_units": "1" } | K20: {'id': 'gen-1780494341-LJ5rk885W2fkwpkdZEiQ', 'object': 'chat.completion', 'created': 1780494341, 'model': 'anthropic/claude-4.7-opus-20260416', 'provider': 'Anthropic', 'system_fingerprint': None, 'service_tier': 'default', 'choices': [{'index': 0, 'logprobs': None, 'finish_reason': 'stop', 'native_finish_reason': 'end_turn', 'message': {'role': 'assistant', 'content': 'Initially: C_series = C/2, U on each = U/2, E_0 = U/(2d).\n\nAfter: C\'_1 = εC, C_2 = C. Series total. Voltage on dielectric cap: U_1 = U·C_2/(C_1\'+C_2) = U/(ε+1).\n\nField in dielectric: E = U_1/(ε·d)... wait, field in dielectric E = U_1/d (the geometric distance), but reduced by ε from free charge. Actually E = U_1/d where d is plate separation.\n\nE/E_0 = [U/((ε+1)d)] / [U/(2d)] = 2/(ε+1).\n\n{\n "final_numeric": null,\n "final_formula": "\\\\dfrac{E}{E_0} = \\\\dfrac{2}{\\\\varepsilon+1}",\n "final_units": "1"\n}', 'refusal': None, 'reasoning': None}}], 'usage': {'prompt_tokens': 940, 'completion_tokens': 285, 'total_tokens': 1225, 'cost': 0.011825, 'is_byok': False, 'prompt_tokens_details': {'cached_tokens': 0, 'cache_write_tokens': 0, 'audio_tokens': 0, 'video_tokens': 0}, 'cost_details': {'upstream_inference_cost': 0.011825, 'upstream_inference_prompt_cost': 0.0047, 'upstream_inference_completions_cost': 0.007125}, 'completion_tokens_details': {'reasoning_tokens': 0, 'image_tokens': 0, 'audio_tokens': 0}}} | L20: 940 | M20: 285 | N20: 1225 | O20: 0 | P20: =VLOOKUP(C20,problems!$A$2:$B$26,2) -> electrostatics | Q20: =IFERROR(__xludf.DUMMYFUNCTION("INDEX(FILTER('stats2-openrouter_activity_2026'!C:C,L20='stats2-openrouter_activity_2026'!H:H,M20='stats2-openrouter_activity_2026'!I:I, B20='stats2-openrouter_activity_2026'!M:M),1)"),0.011825) -> 0.011825 | R20: =IFS( F20=VLOOKUP($C20,problems!$A$2:$G$26,6),1, True,0 ) -> 0 | S20: =IFS( G20=VLOOKUP($C20,problems!$A$2:$G$26,4),1, G20=VLOOKUP($C20,problems!$A$2:$G$26,5),1, True,0 ) -> 0 | T20: =IFS( H20=VLOOKUP($C20,problems!$A$2:$G$26,7),1, True,0 ) -> 1
A21: 2026-06-03-17-47-33 | B21: anthropic/claude-opus-4.7 | C21: 20 | D21: GIven: m — particle's mass -q — charge Particle moves along a straight line away from a fixed particle with charge: Q When the distance between the two particles is r_0 the particle has speed v_0 The interaction between the particles is electrostatic. Find: v_0 — the assumption about the initial speed needed to make the calculation valid. | E21: TRUE | G21: v_0 > \sqrt{\dfrac{kQq}{2\pi\varepsilon_0 m r_0}} = \sqrt{\dfrac{Qq}{2\pi\varepsilon_0 m r_0}} | H21: m/s | J21: {"final_numeric":null,"final_formula":"v_0 > \\sqrt{\\dfrac{kQq}{2\\pi\\varepsilon_0 m r_0}} = \\sqrt{\\dfrac{Qq}{2\\pi\\varepsilon_0 m r_0}}","final_units":"m/s"} | K21: {'id': 'gen-1780494450-JY6O48awL4GWy0htpCJB', 'object': 'chat.completion', 'created': 1780494450, 'model': 'anthropic/claude-4.7-opus-20260416', 'provider': 'Anthropic', 'system_fingerprint': None, 'service_tier': 'default', 'choices': [{'index': 0, 'logprobs': None, 'finish_reason': 'stop', 'native_finish_reason': 'end_turn', 'message': {'role': 'assistant', 'content': '{"final_numeric":null,"final_formula":"v_0 > \\\\sqrt{\\\\dfrac{kQq}{2\\\\pi\\\\varepsilon_0 m r_0}} = \\\\sqrt{\\\\dfrac{Qq}{2\\\\pi\\\\varepsilon_0 m r_0}}","final_units":"m/s"}', 'refusal': None, 'reasoning': None}}], 'usage': {'prompt_tokens': 828, 'completion_tokens': 118, 'total_tokens': 946, 'cost': 0.00709, 'is_byok': False, 'prompt_tokens_details': {'cached_tokens': 0, 'cache_write_tokens': 0, 'audio_tokens': 0, 'video_tokens': 0}, 'cost_details': {'upstream_inference_cost': 0.00709, 'upstream_inference_prompt_cost': 0.00414, 'upstream_inference_completions_cost': 0.00295}, 'completion_tokens_details': {'reasoning_tokens': 0, 'image_tokens': 0, 'audio_tokens': 0}}} | L21: 828 | M21: 118 | N21: 946 | O21: 0 | P21: =VLOOKUP(C21,problems!$A$2:$B$26,2) -> electrostatics | Q21: =IFERROR(__xludf.DUMMYFUNCTION("INDEX(FILTER('stats2-openrouter_activity_2026'!C:C,L21='stats2-openrouter_activity_2026'!H:H,M21='stats2-openrouter_activity_2026'!I:I, B21='stats2-openrouter_activity_2026'!M:M),1)"),0.00709) -> 0.00709 | R21: =IFS( F21=VLOOKUP($C21,problems!$A$2:$G$26,6),1, True,0 ) -> 1 | S21: =IFS( G21=VLOOKUP($C21,problems!$A$2:$G$26,4),1, G21=VLOOKUP($C21,problems!$A$2:$G$26,5),1, True,0 ) -> 0 | T21: =IFS( H21=VLOOKUP($C21,problems!$A$2:$G$26,7),1, True,0 ) -> 0
A22: 2026-06-03-17-48-54 | B22: anthropic/claude-opus-4.7 | C22: 21 | D22: Дано: Атомы водорода испускают монохроматический свет при переходе электронов с некоторой более удалённой орбиты на вторую боровскую орбиту: n -> 2 k — порядок дифракционного максимума. phi — угол дифракции. d = 2.6 мкм — постоянная дифракционной решётки. Пучок света падает на дифракционную решётку по нормали. R — постоянная Ридберга. c — скорость света. Найти: lambda — длина волны испущенного света. | E22: TRUE | G22: \lambda = \frac{d \sin\varphi}{k} | H22: m | J22: {"final_numeric":null,"final_formula":"\\lambda = \\frac{d \\sin\\varphi}{k}","final_units":"m"} | K22: {'id': 'gen-1780494533-WnHctGhkF5QOkNw2pZTo', 'object': 'chat.completion', 'created': 1780494533, 'model': 'anthropic/claude-4.7-opus-20260416', 'provider': 'Anthropic', 'system_fingerprint': None, 'service_tier': 'default', 'choices': [{'index': 0, 'logprobs': None, 'finish_reason': 'stop', 'native_finish_reason': 'end_turn', 'message': {'role': 'assistant', 'content': '{"final_numeric":null,"final_formula":"\\\\lambda = \\\\frac{d \\\\sin\\\\varphi}{k}","final_units":"m"}', 'refusal': None, 'reasoning': None}}], 'usage': {'prompt_tokens': 889, 'completion_tokens': 55, 'total_tokens': 944, 'cost': 0.00582, 'is_byok': False, 'prompt_tokens_details': {'cached_tokens': 0, 'cache_write_tokens': 0, 'audio_tokens': 0, 'video_tokens': 0}, 'cost_details': {'upstream_inference_cost': 0.00582, 'upstream_inference_prompt_cost': 0.004445, 'upstream_inference_completions_cost': 0.001375}, 'completion_tokens_details': {'reasoning_tokens': 0, 'image_tokens': 0, 'audio_tokens': 0}}} | L22: 889 | M22: 55 | N22: 944 | O22: 0 | P22: =VLOOKUP(C22,problems!$A$2:$B$26,2) -> nuclear | Q22: =IFERROR(__xludf.DUMMYFUNCTION("INDEX(FILTER('stats2-openrouter_activity_2026'!C:C,L22='stats2-openrouter_activity_2026'!H:H,M22='stats2-openrouter_activity_2026'!I:I, B22='stats2-openrouter_activity_2026'!M:M),1)"),0.00582) -> 0.00582 | R22: =IFS( F22=VLOOKUP($C22,problems!$A$2:$G$26,6),1, True,0 ) -> 0 | S22: =IFS( G22=VLOOKUP($C22,problems!$A$2:$G$26,4),1, G22=VLOOKUP($C22,problems!$A$2:$G$26,5),1, True,0 ) -> 0 | T22: =IFS( H22=VLOOKUP($C22,problems!$A$2:$G$26,7),1, True,0 ) -> 0
A23: 2026-06-03-17-51-02 | B23: anthropic/claude-opus-4.7 | C23: 22 | D23: Дано: Подводная лодка имеет мощность топливных установок: P = 14.7 МВт n = 25% — КПД установки m_0 = 1 кг — масса урана, для которой дана энергия деления E = 6.9 * 10^13 Дж — энергия, выделяющаяся при делении ядер урана t = 1 год — время плавания Найти: m — масса урана, необходимая для годового плавания лодки, в килограммах. | E23: TRUE | F23: 26.87 | G23: m = \frac{P \cdot t \cdot m_0}{\eta \cdot E} | H23: kg | J23: P*t / n = energy needed from fuel t = 365*24*3600 = 31536000 s P*t = 14.7e6 * 31536000 = 4.6358e14 J /0.25 = 1.8543e15 J m = m0 * E_needed / E = 1.8543e15 / 6.9e13 = 26.87 kg { "final_numeric": 26.87, "final_formula": "m = \\frac{P \\cdot t \\cdot m_0}{\\eta \\cdot E}", "final_units": "kg" } | K23: {'id': 'gen-1780494657-LxdRSJ6JmXx8qk4u54Ru', 'object': 'chat.completion', 'created': 1780494657, 'model': 'anthropic/claude-4.7-opus-20260416', 'provider': 'Anthropic', 'system_fingerprint': None, 'service_tier': 'default', 'choices': [{'index': 0, 'logprobs': None, 'finish_reason': 'stop', 'native_finish_reason': 'end_turn', 'message': {'role': 'assistant', 'content': 'P*t / n = energy needed from fuel\nt = 365*24*3600 = 31536000 s\nP*t = 14.7e6 * 31536000 = 4.6358e14 J\n/0.25 = 1.8543e15 J\nm = m0 * E_needed / E = 1.8543e15 / 6.9e13 = 26.87 kg\n\n{\n "final_numeric": 26.87,\n "final_formula": "m = \\\\frac{P \\\\cdot t \\\\cdot m_0}{\\\\eta \\\\cdot E}",\n "final_units": "kg"\n}', 'refusal': None, 'reasoning': None}}], 'usage': {'prompt_tokens': 870, 'completion_tokens': 192, 'total_tokens': 1062, 'cost': 0.00915, 'is_byok': False, 'prompt_tokens_details': {'cached_tokens': 0, 'cache_write_tokens': 0, 'audio_tokens': 0, 'video_tokens': 0}, 'cost_details': {'upstream_inference_cost': 0.00915, 'upstream_inference_prompt_cost': 0.00435, 'upstream_inference_completions_cost': 0.0048}, 'completion_tokens_details': {'reasoning_tokens': 0, 'image_tokens': 0, 'audio_tokens': 0}}} | L23: 870 | M23: 192 | N23: 1062 | O23: 0 | P23: =VLOOKUP(C23,problems!$A$2:$B$26,2) -> nuclear | Q23: =IFERROR(__xludf.DUMMYFUNCTION("INDEX(FILTER('stats2-openrouter_activity_2026'!C:C,L23='stats2-openrouter_activity_2026'!H:H,M23='stats2-openrouter_activity_2026'!I:I, B23='stats2-openrouter_activity_2026'!M:M),1)"),0.00915) -> 0.00915 | R23: =IFS( F23=VLOOKUP($C23,problems!$A$2:$G$26,6),1, True,0 ) -> 0 | S23: =IFS( G23=VLOOKUP($C23,problems!$A$2:$G$26,4),1, G23=VLOOKUP($C23,problems!$A$2:$G$26,5),1, True,0 ) -> 0 | T23: =IFS( H23=VLOOKUP($C23,problems!$A$2:$G$26,7),1, True,0 ) -> 1
A24: 2026-06-03-17-53-08 | B24: anthropic/claude-opus-4.7 | C24: 23 | D24: Дано: delta n_0 = 250 — начальное число импульсов за минуту. t = 1 ч delta n = 92 — число импульсов за минуту через время t. Найти: T_{1/2} — период полураспада данного изотопа, в минутах. | E24: TRUE | F24: 41.6 | G24: T_{1/2}=\frac{t\ln 2}{\ln(\Delta n_0/\Delta n)} | H24: min | J24: {"final_numeric":41.6,"final_formula":"T_{1/2}=\\frac{t\\ln 2}{\\ln(\\Delta n_0/\\Delta n)}","final_units":"min"} | K24: {'id': 'gen-1780494786-yc2cxFSbAUNAFqh0WwE7', 'object': 'chat.completion', 'created': 1780494786, 'model': 'anthropic/claude-4.7-opus-20260416', 'provider': 'Anthropic', 'system_fingerprint': None, 'service_tier': 'default', 'choices': [{'index': 0, 'logprobs': None, 'finish_reason': 'stop', 'native_finish_reason': 'end_turn', 'message': {'role': 'assistant', 'content': '{"final_numeric":41.6,"final_formula":"T_{1/2}=\\\\frac{t\\\\ln 2}{\\\\ln(\\\\Delta n_0/\\\\Delta n)}","final_units":"min"}', 'refusal': None, 'reasoning': None}}], 'usage': {'prompt_tokens': 804, 'completion_tokens': 76, 'total_tokens': 880, 'cost': 0.00592, 'is_byok': False, 'prompt_tokens_details': {'cached_tokens': 0, 'cache_write_tokens': 0, 'audio_tokens': 0, 'video_tokens': 0}, 'cost_details': {'upstream_inference_cost': 0.00592, 'upstream_inference_prompt_cost': 0.00402, 'upstream_inference_completions_cost': 0.0019}, 'completion_tokens_details': {'reasoning_tokens': 0, 'image_tokens': 0, 'audio_tokens': 0}}} | L24: 804 | M24: 76 | N24: 880 | O24: 0 | P24: =VLOOKUP(C24,problems!$A$2:$B$26,2) -> nuclear | Q24: =IFERROR(__xludf.DUMMYFUNCTION("INDEX(FILTER('stats2-openrouter_activity_2026'!C:C,L24='stats2-openrouter_activity_2026'!H:H,M24='stats2-openrouter_activity_2026'!I:I, B24='stats2-openrouter_activity_2026'!M:M),1)"),0.00592) -> 0.00592 | R24: =IFS( F24=VLOOKUP($C24,problems!$A$2:$G$26,6),1, True,0 ) -> 0 | S24: =IFS( G24=VLOOKUP($C24,problems!$A$2:$G$26,4),1, G24=VLOOKUP($C24,problems!$A$2:$G$26,5),1, True,0 ) -> 0 | T24: =IFS( H24=VLOOKUP($C24,problems!$A$2:$G$26,7),1, True,0 ) -> 1
